Workbook
Name Print_Area_MI: #REF!
Name Print_Area_MI: #REF!
Name Print_Area_MI: #REF!

Sheet PIPELINE & CABLE
C1: SAUDI ARABIAN OIL COMPANY - LONG TERM AGREEMENT (LTA) FOR OFFSHORE FACILITIES CRPO FOR JU'AYMAH OFFSHORE PLATFORM - BYPASS SYSTEM | N1: NPCC DOC. No.:
N2: CLIENT DOC. No. :
C3: NPCC PROJECT NO. 2171 (OOK)/ 2172 (IK) | N3: REVISION : | R3: 0
C4: OFFSHORE CONSTRUCTION ENGINEERING DOCUMENTS (PIPELINE & CABLE) | N4: DATE : | R4: 44524
A5: SR. NO. | B5: DESCRIPTION | C5: NPCC DOCUMENT NUMBER | D5: REV. | E5: CLASS | F5: SUBMISSION PLANNED DATE | G5: NPCC | K5: CLIENT | N5: GMC | S5: REMARKS
G6: SUBMISSION STATUS | K6: APPROVAL STATUS | N6: SUBMISSION STATUS | P6: APPROVAL STATUS
G7: CSE TO PMT | I7: PMT TO CLIENT | K7: FROM CLIENT | N7: PMT TO GMC | P7: STATUS FROM GMC
G8: DATE | H8: REF | I8: DATE | J8: REF | K8: DATE | L8: REF | M8: CODE | N8: DATE | O8: REF | P8: DATE | Q8: REF | R8: CODE
A10: 1 | B10: PIPE STACKING ANALYSIS REPORT | C10: 2171-2172-NN-RP-001 | D10: A | F10: 44563 | G10: 44571 | H10: CSE-2171-72-PMT-T-004 | I10: 44575 | J10: 2171-2172-NPCC-T-0878 | K10: 44594 | L10: CPD-JOPB-T-0156-22 | M10: 2
D11: B | G11: 44615 | H11: CSE-2171-72-PMT-T-007 | I11: 44622 | J11: 2171-2172-NPCC-T-1034 | K11: 44635 | L11: CPD-JOPB-T-0387-22 | M11: 1
A12: 2 | B12: PIPELAY ANALYSIS REPORT FOR 48" BYPASS PIPELINES | C12: 2171-2172-NN-RP-002 | D12: A | F12: 44564 | G12: 44620 | H12: CSE-2171-72-PMT-T-010 | I12: 44624 | J12: 2171-2172-NPCC-T-1048 | K12: 44654 | L12: CPD-JOPB-T-0494-22 | M12: 2
D13: B | G13: 44664 | H13: CSE-2171-72-PMT-T-019 | I13: 44665 | J13: 2171-2172-NPCC-T-1171 | K13: 44676 | L13: CPD-JOPB-T-0629-22 | M13: 1
D14: 00 | G14: 44680 | H14: CSE-2171-72-PMT-T-021 | I14: 44680 | J14: 2171-2172-NPCC-T-1227
A15: 3 | B15: PIPELAY ANALYSIS REPORT FOR 48" BYPASS PIPELINE 2 FROM CLS 22 TIE-IN TO PLEM 31 / SPM 31 & PLEM 33 / SPM 33 | C15: 2171-2172-NN-RP-003 | F15: 44568
A16: 4 | B16: PIPELAY ANALYSIS REPORT FOR 48" BYPASS PIPELINE 3 FROM CLS 23 TIE-IN TO PLEM 36 / SPM 36 | C16: 2171-2172-NN-RP-004 | F16: 44575
A17: 5 | B17: PIPELAY ANALYSIS REPORT FOR 48" BYPASS PIPELINE 4 FROM CLS 24 TIE-IN TO PLEM 34 / SPM 34 & PLEM 35 / SPM 35 | C17: 2171-2172-NN-RP-005 | F17: 44582
A18: 6 | B18: SPOOL LIFTING ANALYSIS REPORT FOR 48" BYPASS PIPELINE-1 | C18: 2171-2172-NN-RP-006 | D18: 1 | E18: 2 | F18: 44616 | G18: 44932 | H18: CSE-2171-72-PMT-T-052 | S18: govering by midline spool
A19: 7 | B19: SPOOL LIFTING ANALYSIS REPORT FOR 48" BYPASS | C19: 2171-2172-NN-RP-007 | F19: 44619
A20: 8 | B20: SPOOL LIFTING ANALYSIS REPORT FOR 48" BYPASS PIPELINE-2,3 & 4 BY TELFORD-25 | C20: 2171-2172-NN-RP-008 | D20: 1 | E20: 2 | F20: 44798 | G20: 44951 | H20: CSE-2171-72-PMT-T-060
A21: 9 | B21: SPOOL LIFTING ANALYSIS REPORT FOR 48" BYPASS PIPELINE-4 | C21: 2171-2172-NN-RP-009 | F21: 44850
A22: 10 | B22: SEAFASTENING DESIGN REPORT FOR TRANSPORTATION OF HTF, SSVS & SPOOLS ON CREST-287 | C22: 2171-2172-NN-RP-010 | D22: A | E22: 3 | F22: 44646 | G22: 44776 | H22: CSE-2171-72-PMT-T-030 | I22: 44791 | J22: 2171-2172-NPCC-T-1540 | N22: 44791 | O22: 2171-2172-NPCC-MWS-T-0016 | P22: 44819 | Q22: BAS1178-TRN-018 | R22: ACCEPTED WITH CONDITION
A23: 11 | B23: SEAFASTENING DESIGN REPORT FOR TRANSPORTATION OF HTF, SSVS & SPOOLS ON MICLYN-259 | C23: 2171-2172-NN-RP-011 | D23: A | E23: 3 | F23: 44654 | G23: 44776 | H23: CSE-2171-72-PMT-T-029 | I23: 44791 | J23: 2171-2172-NPCC-T-1539 | N23: 44791 | O23: 2171-2172-NPCC-MWS-T-0015 | P23: 44819 | Q23: BAS1178-TRN-019 | R23: ACCEPTED WITH CONDITION
D24: B | E24: 3 | G24: 44841 | H24: CSE-2171-72-PMT-T-035 | I24: 44846 | J24: 2171-2172-NPCC-T-1684 | N24: 44846 | O24: 2171-2172-NPCC-MWS-T-0018 | P24: 44870 | Q24: BAS1178-TRN 019 | R24: Approved
A25: 12 | B25: SEAFASTENING DESIGN REPORT FOR TRANSPORTATION OF CC PIPES ON CREST-287 | C25: 2171-2172-NN-RP-012 | D25: A | E25: 3 | F25: 44564 | G25: 44636 | H25: CSE-2171-72-PMT-T-012 | I25: 44638 | J25: 2171-2172-NPCC-T-1089 | N25: 44638 | O25: 2171-2172-NPCC-MWS-T-0003 | P25: 44670 | Q25: BAS1178-TRN 004 | R25: comments
A26: 13 | B26: SEAFASTENING DESIGN REPORT FOR TRANSPORTATION OF CC PIPES ON MICLYN-259 | C26: 2171-2172-NN-RP-013 | D26: A | E26: 3 | F26: 44595 | G26: 44644 | H26: CSE-2171-72-PMT-T-016 | I26: 44671 | J26: 2171-2172-NPCC-T-1194 | N26: 44671 | O26: 2171-2172-NPCC-MWS-T-0007 | P26: 44700 | Q26: BAS1178-TRN 011 | R26: ACCEPTED WITH CONDITION
A27: 14 | B27: SEAFASTENING DESIGN REPORT FOR TRANSPORTATION OF CONCRETE SLEEPERS ON CREST-287 | C27: 2171-2172-NN-RP-014 | D27: A | E27: 3 | F27: 44564 | G27: 44643 | H27: CSE-2171-72-PMT-T-015 | I27: 44648 | J27: 171-2172-NPCC-T-1099 | N27: 44648 | O27: 2171-2172-NPCC-MWS-T-0005 | P27: 44670 | Q27: BAS1178-TRN 007 | R27: comments
A28: 15 | B28: SEAFASTENING DESIGN REPORT FOR TRANSPORTATION OF STINGER & MISC. ITEMS ON ALLIANZ CB-250 | C28: 2171-2172-NN-RP-015 | D28: A | E28: 3 | F28: =F12 -> 44564 | G28: 44651 | H28: CSE-2171-72-PMT-T-018 | I28: 44654 | J28: 2171-2172-NPCC-T-1137 | N28: 44654 | O28: 2171-2172-NPCC-MWS-T-0006 | P28: 44670 | Q28: BAS1178-TRN 009 | R28: comments
A29: 16 | B29: SEAFASTENING DESIGN REPORT FOR TRANSPORTATION OF CC PIPES ON GOGAS-252. | C29: 2171-2172-NN-RP-016 | D29: A | E29: 3 | G29: 44699 | H29: CSE-2171-72-PMT-T-022 | I29: 44700 | J29: 2171-2172-NPCC-T-1272 | N29: 44700 | O29: 2171-2172-NPCC-MWS-T-0009 | P29: 44710 | Q29: BAS1178-TRN 013 | R29: ACCEPTED WITH CONDITION
A30: 17 | B30: SEAFASTENING DESIGN REPORT FOR TRANSPORTATION OF CC PIPES ON PFC-02 | C30: 2171-2172-NN-RP-017 | D30: A | E30: 3 | G30: 44699 | H30: CSE-2171-72-PMT-T-023 | I30: 44700 | J30: 2171-2172-NPCC-T-1270 | N30: 44700 | O30: 2171-2172-NPCC-MWS-T-0008 | P30: 44710 | Q30: BAS1178-TRN 015 | R30: ACCEPTED WITH CONDITION
A31: 18 | B31: SEAFASTENING DESIGN REPORT FOR TRANSPORTATION OF HTF & MISC. ITEMS ON MICLYN-258 | C31: 2171-2172-NN-RP-018 | D31: A | E31: 3 | G31: 44797 | H31: CSE-2171-72-PMT-T-032 | N31: -- | O31: -- | P31: 44799 | Q31: BAS-1178-TRN-016 | R31: Approved
A32: 19 | B32: SEAFASTENING DESIGN REPORT FOR TRANSPORTATION OF FLUSHING EQP. & MISC. ITEMS ON MICLYN-258 | C32: 2171-2172-NN-RP-019 | D32: A | E32: 3 | G32: 44845 | H32: CSE-2171-72-PMT-T-036
D33: B | E33: 3 | G33: 45085 | H33: CSE-2171-72-PMT-T-066 | N33: -- | O33: Email from Hisham Qazani | P33: 45089 | Q33: BAS1178-TRN 030 | R33: ACCEPTED WITH CONDITION
A34: 20 | B34: SEAFASTENING DESIGN REPORT FOR TRANSPORTATION OF TANK, SSVS & SPOOLS ON GAC-81 | C34: 2171-2172-NN-RP-020 | D34: A | E34: 3 | G34: 44880 | H34: CSE-2171-72-PMT-T-039 | I34: 44883 | J34: 2171-2172-NPCC-T-1731 | N34: 44883 | O34: 2171-2172-NPCC-MWS-T-0021 | P34: 44886 | Q34: BAS1178-TRN 023 | R34: ACCEPTED WITH CONDITION
A35: 21 | B35: SEAFASTENING DESIGN REPORT FOR TRANSPORTATION OF SSVS, SPOOLS & SHROUD ON CREST-287 | C35: 2171-2172-NN-RP-021 | D35: A | E35: 3 | G35: 44916 | H35: CSE-2171-72-PMT-T-046 | I35: 44916 | J35: 2171-2172-NPCC-T-1767 | N35: 44916 | O35: 2171-2172-NPCC-MWS-T-0025
A36: 22 | B36: SEAFASTENING DESIGN REPORT FOR TRANSPORTATION OF SPOOLS ON GOGAS-250 | C36: 2171-2172-NN-RP-022 | D36: A | E36: 3 | G36: 44922 | H36: CSE-2171-72-PMT-T-049 | I36: 44922 | J36: 2171-2172-NPCC-T-1771 | N36: 44922 | O36: 2171-2172-NPCC-MWS-T-0028 | P36: 44932 | Q36: BAS1178-TRN 026 | R36: ACCEPTED WITH CONDITION
A37: 23 | B37: SEAFASTENING DESIGN REPORT FOR TRANSPORTATION OF SSVS, SPOOLS AND SLEEPERS ON EOS-283 | C37: 2171-2172-NN-RP-023 | D37: A | E37: 3 | G37: 44924 | H37: CSE-2171-72-PMT-T-050 | I37: 44924 | J37: 2171-2172-NPCC-T-1774 | N37: 44924 | O37: 2171-2172-NPCC-MWS-T-0030 | P37: 44932 | Q37: BAS1178-TRN 028 | R37: ACCEPTED WITH CONDITION
A38: 24 | B38: SEAFASTENING DESIGN REPORT FOR MATERIAL TEMPORARY STORAGE ON LB-II | C38: 2171-2172-NN-RP-024 | D38: A | E38: 3 | G38: 45071 | H38: CSE-2171-72-PMT-T-065 | I38: 45075 | J38: 2171-2172-NPCC-T-1865 | N38: 45075 | O38: 2171-2172-NPCC-MWS-T-0031 | P38: 45091 | Q38: BAS1178-TRN 032 | R38: ACCEPTED WITH CONDITION
A39: 25 | B39: SEAFASTENING DESIGN REPORT FOR HOT TAP FRAME TRANSPORTATION ON CB-6 | C39: 2171-2172-NN-RP-025 | D39: A | E39: 3 | G39: 45120 | H39: CSE-2171-72-PMT-T-069
A40: 26 | B40: SEAFASTENING DESIGN REPORT FOR TRANSPORTATION OF SSVS AND SPOOLS ON EOS 283 | C40: 2171-2172-NN-RP-026 | D40: A | E40: 3 | G40: 45321 | H40: CSE-2171-72-PMT-T-073 | I40: 45322 | J40: 2171-2172-NPCC-T-1971 | N40: 45322 | O40: 2171-2172-NPCC-MWS-T-0034 | P40: 45329 | Q40: BAS1178-TRN 035 | R40: ACCEPTED WITH CONDITION
A41: 27 | B41: SEAFASTENING DESIGN REPORT FOR TRANSPORTATION OF SPOOLS AND SLEEPERS ON GAC -81 | C41: 2171-2172-NN-RP-027 | D41: A | E41: 3 | G41: 45328 | H41: CSE-2171-72-PMT-T-075 | I41: 45403 | J41: 2171-2172-NPCC-T-2017 | N41: 45401 | O41: 2171-2172-NPCC-MWS-T-0036 | P41: 45403 | Q41: BAS1178-TRN 038 | R41: ACCEPTED WITH CONDITION
...

Sheet Documents - Naval & Marine
C1: SAUDI ARABIAN OIL COMPANY - LONG TERM AGREEMENT (LTA) FOR OFFSHORE FACILITIES CRPO FOR JU'AYMAH OFFSHORE PLATFORM - BYPASS SYSTEM | N1: NPCC DOC. No.:
N2: CLIENT DOC. No. :
C3: NPCC PROJECT NO. 2171 (OOK)/ 2172 (IK) | N3: REVISION : | R3: 0
C4: OFFSHORE CONSTRUCTION ENGINEERING DOCUMENTS (NAVAL & MARINE) | N4: DATE : | R4: ='PIPELINE & CABLE'!R4:S4 -> 44524
A5: SR. NO. | B5: DESCRIPTION | C5: NPCC DOCUMENT NUMBER | D5: REV. | E5: CLASS | F5: SUBMISSION PLANNED DATE | G5: NPCC | K5: CLIENT | N5: GMC | S5: REMARKS
G6: SUBMISSION STATUS | K6: APPROVAL STATUS | N6: SUBMISSION STATUS | P6: APPROVAL STATUS
G7: CSE TO PMT | I7: PMT TO CLIENT | K7: FROM CLIENT | N7: PMT TO GMC | P7: STATUS FROM GMC
G8: DATE | H8: REF | I8: DATE | J8: REF | K8: DATE | L8: REF | M8: CODE | N8: DATE | O8: REF | P8: DATE | Q8: REF | R8: CODE
A9: 1 | B9: MOORING ANALYSIS FOR DLB-750 DURING LAYING OF PIPELINE #1 & 2 | C9: 2171-2172-ZZ-CL-001 | D9: A | E9: 2 | F9: ='PIPELINE & CABLE'!F12 -> 44564 | G9: 44628 | H9: CSE-2171-72-PMT-T-011 | I9: 44630 | J9: 2171-2172-NPCC-T-1061 | K9: 44644 | L9: CPD-JOPB-T-0438-22 | M9: 5 | N9: 44630 | O9: 2171-2172-NPCC-MWS-T-0001 | P9: 44670 | Q9: BAS1178-TRN 001 | R9: comments | S9: suby
A10: 2 | B10: MOORING ANALYSIS FOR DLB-750 DURING LAYING OF PIPELINE # 3 | C10: 2171-2172-ZZ-CL-002 | D10: A | E10: 2 | F10: ='PIPELINE & CABLE'!F15 -> 44568 | G10: 23/02/2022 10/03/2022 | H10: CSE-2171-72-PMT-T-008 | I10: 44635 | J10: 2171-2172-NPCC-T-1070 | K10: 44651 | L10: CPD-JOPB-T-0476-22 | M10: 5 | N10: 44635 | O10: 2171-2172-NPCC-MWS-T-0002 | P10: 44670 | Q10: BAS1178-TRN 002 | R10: comments | S10: doc. modified on 10/03
A11: 3 | B11: MOORING ANALYSIS DURING WEATHER STANDBY POSITION FOR PIPELINE - 1 & 2 | C11: 2171-2172-ZZ-CL-003 | D11: A | E11: 2 | F11: ='PIPELINE & CABLE'!F16 -> 44575 | G11: 44637 | H11: CSE-2171-72-PMT-T-014 | I11: 44643 | J11: 2171-2172-NPCC-T-1098 | K11: 44656 | L11: CPD-JOPB-T-0503-22 | M11: 5 | N11: 44643 | O11: 2171-2172-NPCC-MWS-T-0004 | P11: 44670 | Q11: BAS1178-TRN 005 | R11: comments
A12: 4 | B12: MOORING ANALYSIS DURING WEATHER STANDBY POISITION FOR PIPELINE - 3 & 4 | C12: 2171-2172-ZZ-CL-004 | D12: A | E12: 2 | F12: ='PIPELINE & CABLE'!F17 -> 44582 | G12: 44649 | H12: CSE-2171-72-PMT-T-017
A13: 5 | B13: STABILITY ANALYSIS DURING TRANSPORTATION OF CC PIPES TRIP1 AT CREST 287 | C13: 2171-2172-ZZ-CL-005 | D13: A | E13: 3 | F13: ='PIPELINE & CABLE'!F25 -> 44564 | G13: 44636 | H13: CSE-2171-72-PMT-T-012 | I13: 44638 | J13: 2171-2172-NPCC-T-1089 | N13: 44643 | O13: 2171-2172-NPCC-MWS-T-0003 | P13: 44670 | Q13: BAS1178-TRN 003 | R13: comments
A14: 6 | B14: STABILITY ANALYSIS DURING TRANSPORTATION OF CC PIPES TRIP-2 @ MICLYIN 259 | C14: 2171-2172-ZZ-CL-006 | D14: A | E14: 3 | F14: ='PIPELINE & CABLE'!F26 -> 44595 | G14: 44644 | H14: CSE-2171-72-PMT-T-016 | I14: 44671 | J14: 2171-2172-NPCC-T-1194 | N14: 44671 | O14: 2171-2172-NPCC-MWS-T-0007 | P14: 44700 | Q14: BAS1178-TRN 010 | R14: ACCEPTED WITH CONDITION
A15: 7 | B15: STABILITY ANALYSIS FOR TRANSPORTATION OF HOT TAP FRAME, VALVE SKID & SPOOLS FOR CFL-32 @ CREST 287 | C15: 2171-2172-ZZ-CL-007 | D15: A | E15: 3 | F15: ='PIPELINE & CABLE'!F22 -> 44646 | G15: 44788 | H15: CSE-2171-72-PMT-T-030 | I15: 44791 | J15: 2171-2172-NPCC-T-1540 | N15: 44791 | O15: 2171-2172-NPCC-MWS-T-0016 | P15: 44819 | Q15: BAS1178-TRN-022 | R15: ACCEPTED WITH CONDITION
A16: 8 | B16: STABILITY ANALYSIS FOR TRANSPORTATION OF HOT TAP FRAME, VALVE SKID & SPOOLS FOR CLS-22 @ MICLYIN-259 | C16: 2171-2172-ZZ-CL-008 | D16: A | E16: 3 | F16: ='PIPELINE & CABLE'!F23 -> 44654 | G16: 44788 | H16: CSE-2171-72-PMT-T-029 | I16: 44791 | J16: 2171-2172-NPCC-T-1539 | N16: 44791 | O16: 2171-2172-NPCC-MWS-T-0015 | P16: 44819 | Q16: BAS1178-TRN-021 | R16: ACCEPTED WITH CONDITION
D17: B | E17: 3 | G17: 44841 | H17: CSE-2171-72-PMT-T-035 | I17: 44846 | J17: 2171-2172-NPCC-T-1684 | N17: 44846 | O17: 2171-2172-NPCC-MWS-T-0018 | P17: 44859 | Q17: BAS1178-TRN 021 | R17: ACCEPTED WITH CONDITION
D18: C | E18: 3 | G18: 45064 | H18: CSE-2171-72-PMT-T-064 | N18: 45064 | O18: EMAIL | P18: 45065 | Q18: BAS1178-TRN 029 | R18: ACCEPTED WITH CONDITION
A19: 9 | B19: STABILITY ANALYSIS FOR TRANSPORTATION OF CONCRETE SLEEPERS @ CREST 287 | C19: 2171-2172-ZZ-CL-009 | D19: A | E19: 3 | F19: ='PIPELINE & CABLE'!F27 -> 44564 | G19: 44643 | H19: CSE-2171-72-PMT-T-015 | I19: 44648 | J19: 2171-2172-NPCC-T-1099 | N19: 44648 | O19: 2171-2172-NPCC-MWS-T-0005 | P19: 44670 | Q19: BAS1178-TRN 006 | R19: comments
A20: 10 | B20: MOORING ANALYSIS DURING SPOOL INSTALLATIONS FOR PIPELINE 1 & 2 | C20: 2171-2172-ZZ-CL-010 | F20: ='PIPELINE & CABLE'!F18 -> 44616
A21: 11 | B21: MOORING ANALYSIS DURING SPOOL INSTALLATIONS FOR PIPELINE 3 & 4 | C21: 2171-2172-ZZ-CL-011 | F21: ='PIPELINE & CABLE'!F19 -> 44619
A22: 12 | B22: STABILITY ANALYSIS DURING TRANSPORTATION OF VALVE SKIDS, SPOOLS & SHROUDS @ LB-II | C22: 2171-2172-ZZ-CL-012 | D22: A | E22: 3 | G22: 45071 | H22: CSE-2171-72-PMT-T-065 | I22: 45075 | J22: 2171-2172-NPCC-T-1865 | N22: 45075 | O22: 2171-2172-NPCC-MWS-T-0031 | P22: 45093 | Q22: BAS1178-TRN 033 | R22: OPEN COMMENTS
A23: 13 | B23: MOORING ANALYSIS DURING SUBSEA VALVE SKID & SPOOLS INSTALLATION AT CLS-21 INSTALLATION AT CLS-21 | C23: 2171-2172-ZZ-CL-013 | D23: A | E23: 2 | G23: 44908 | H23: CSE-2171-72-PMT-T-043 | I23: 44910 | J23: 2171-2172-NPCC-T-1763 | N23: 44910 | O23: 2171-2172-NPCC-MWS-T-0024 | S23: prashanth
A24: 14 | B24: STABILITY ANALYSIS DURING TRANSPORTATION OF STINGER X SEC A AND MISC ITEMS @ ALLIANZ CB-250 | C24: 2171-2172-ZZ-CL-014 | D24: A | E24: 3 | G24: 44651 | H24: CSE-2171-72-PMT-T-018 | I24: 44654 | J24: 2171-2172-NPCC-T-1137 | N24: 44654 | O24: 2171-2172-NPCC-MWS-T-0006 | P24: 44670 | Q24: BAS1178-TRN 008 | R24: comments
A25: 15 | B25: STABILITY ANALYSIS FOR PFC-02 DURING TRANSPORTATION OF 48INCH PIPES FOR SPOOL | C25: 2171-2172-ZZ-CL-015 | D25: A | E25: 3 | G25: 44699 | H25: CSE-2171-72-PMT-T-023 | I25: 44700 | J25: 2171-2172-NPCC-T-1270 | N25: 44700 | O25: 2171-2172-NPCC-MWS-T-0008 | P25: 44710 | Q25: BAS1178-TRN 014 | R25: ACCEPTED WITH CONDITION
A26: 16 | B26: STABILITY ANALYSIS FOR TRANSPORTATION OF CC PIPES TRIP-3 @ GOGAS-252 | C26: 2171-2172-ZZ-CL-016 | D26: A | E26: 3 | G26: 44699 | H26: CSE-2171-72-PMT-T-022 | I26: 44700 | J26: 2171-2172-NPCC-T-1272 | N26: 44700 | O26: 2171-2172-NPCC-MWS-T-0009 | P26: 44710 | Q26: BAS1178-TRN 012 | R26: ACCEPTED WITH CONDITION
A27: 17 | B27: STABILITY ANALYSIS FOR CARGO BARGE MICLYN-258 | C27: 2171-2172-ZZ-CL-017 | D27: A | E27: 3 | G27: 44797 | H27: CSE-2171-72-PMT-T-032 | N27: -- | O27: -- | P27: 44799 | Q27: BAS1178-TRN-017 | R27: ACCEPTED WITH CONDITION
D28: B | E28: 3 | G28: 44845 | H28: CSE-2171-72-PMT-T-036
D29: C | E29: 3 | G29: 45085 | H29: CSE-2171-72-PMT-T-066 | N29: -- | O29: Email from Hisham Qazani | P29: 45089 | Q29: BAS1178-TRN 031 | R29: ACCEPTED WITH CONDITION
A30: 18 | B30: STABILITY ANALYSIS DURING TRANSPORTATION OF VALVE SKID, SPOOLS & CABLE TANK FOR CLS-21 @ GAC-81 | C30: 2171-2172-ZZ-CL-018 | D30: A | E30: 3 | G30: 44880 | H30: CSE-2171-72-PMT-T-039 | I30: 44883 | J30: 2171-2172-NPCC-T-1731 | N30: 44883 | O30: 2171-2172-NPCC-MWS-T-0021 | P30: 44886 | Q30: BAS1178-TRN 024 | R30: ACCEPTED WITH CONDITION
A31: 19 | B31: MOORING ANALYSIS DURING SUBSEA VALVE SKID & SPOOLS INSTALLATION AT CLS-24 | C31: 2171-2172-ZZ-CL-019 | D31: A | E31: 2 | G31: 44907 | H31: CSE-2171-72-PMT-T-042 | I31: 44910 | J31: 2171-2172-NPCC-T-1762 | N31: 44910 | O31: 2171-2172-NPCC-MWS-T-0023
A32: 20 | B32: STABILITY ANALYSIS FOR TRANSPORTATION OF VALVE SKID, SPOOLS, SHROUDS & SLEEPERS FOR CFL-33 & 35 @ EOS-283 | C32: 2171-2172-ZZ-CL-020 | D32: A | E32: 3 | G32: 44915 | H32: CSE-2171-72-PMT-T-045 | I32: 44916 | J32: 2171-2172-NPCC-T-1768 | N32: 44917 | O32: 2171-2172-NPCC-MWS-T-0026 | P32: 44932 | Q32: BAS1178-TRN 027 | R32: ACCEPTED WITH CONDITION
A33: 21 | B33: STABILITY ANALYSIS FOR TRANSPORTATION OF SPOOLS & SHROUDS @ GOGAS-250 | C33: 2171-2172-ZZ-CL-021 | D33: A | E33: 3 | G33: 44917 | H33: CSE-2171-72-PMT-T-047 | I33: 44918 | J33: 2171-2172-NPCC-T-1770 | N33: 44918 | O33: 2171-2172-NPCC-MWS-T-0027 | P33: 44932 | Q33: BAS1178-TRN 025 | R33: ACCEPTED WITH CONDITION
A34: 22 | B34: MOORING ANALYSIS DURING REMEDIAL WORK RECTIFICATION OF HOT TAPPING OPERATION AT CFL-34 | C34: 2171-2172-ZZ-CL-022 | D34: A | E34: 2 | G34: 45117 | H34: CSE-2171-72-PMT-T-068 | N34: 45122 | O34: 2171-2172-NPCC-MWS-T-0033 | P34: 45127 | Q34: BAS1178-TRN 034 | R34: comments
D35: B | E35: 2 | G35: 45135 | H35: CSE-2171-72-PMT-T-070 | N35: 45135 | O35: email | P35: 45140 | Q35: BAS1178-TRN 034 | R35: ACCEPTED WITH CONDITION
A36: 23 | B36: STABILITY ANALYSIS FOR CARGO BARGE CB-6 | C36: 2171-2172-ZZ-CL-023 | D36: A | E36: 3 | G36: 45120 | H36: CSE-2171-72-PMT-T-069
A37: 24 | B37: STABILITY ANALYSIS FOR CARGO BARGE EOS-283 LOADED WITH VALVE SKIDS, SPOOLS AND SHROUDS | C37: 2171-2172-ZZ-CL-024 | D37: A | E37: 3 | G37: 45321 | H37: CSE-2171-72-PMT-T-073 | I37: 45322 | J37: 2171-2172-NPCC-T-1971 | N37: 45322 | O37: 2171-2172-NPCC-MWS-T-0034 | P37: 45336 | Q37: BAS1178-TRN 036 | R37: ACCEPTED WITH CONDITION
A38: 25 | B38: STABILITY ANALYSIS FOR CARGO BARGE GAC-81 LOADED WITH SLEEPERS AND SPOOLS | C38: 2171-2172-ZZ-CL-025 | D38: A | E38: 3 | G38: 45328 | H38: CSE-2171-72-PMT-T-075 | I38: 45403 | J38: 2171-2172-NPCC-T-2017 | N38: 45401 | O38: 2171-2172-NPCC-MWS-T-0036 | P38: 45403 | Q38: BAS1178-TRN 037 | R38: ACCEPTED WITH CONDITION
A39: 26 | B39: STABILITY ANALYSIS FOR CARGO BARGE GAC-81 WITH HOT TAP FRAMES & LAY DOWN HEADS ONBOARD | C39: 2171-2172-ZZ-CL-026 | D39: A | E39: 3 | G39: 45518 | H39: CSE-2171-72-PMT-T-084 | N39: 45527 | O39: 2171-2172-NPCC-MWS-T-0039 | P39: 45542 | Q39: BAS1178-TRN 039 | R39: ACCEPTED WITH CONDITION
D40: B | E40: 3 | G40: 45555 | H40: CSE-2171-72-PMT-T-088
...

Sheet DRAWINGS
C1: SAUDI ARABIAN OIL COMPANY - LONG TERM AGREEMENT (LTA) FOR OFFSHORE FACILITIES CRPO FOR JU'AYMAH OFFSHORE PLATFORM - BYPASS SYSTEM | N1: NPCC DOC. No.:
N2: CLIENT DOC. No. :
C3: NPCC PROJECT NO. 2171 (OOK)/ 2172 (IK) | N3: REVISION : | R3: 0
C4: OFFSHORE CONSTRUCTION ENGINEERING DOCUMENTS (PIPELINE & CABLE) | N4: DATE : | R4: ='PIPELINE & CABLE'!R4:S4 -> 44524
A5: SR. NO. | B5: DESCRIPTION | C5: NPCC DOCUMENT NUMBER | D5: REV. | E5: CLASS | F5: SUBMISSION PLANNED DATE | G5: NPCC | K5: CLIENT | N5: GMC | S5: REMARKS
G6: SUBMISSION STATUS | K6: APPROVAL STATUS | N6: SUBMISSION STATUS | P6: APPROVAL STATUS
G7: CSE TO PMT | I7: PMT TO CLIENT | K7: FROM CLIENT | N7: PMT TO GMC | P7: STATUS FROM GMC
G8: DATE | H8: REF | I8: DATE | J8: REF | K8: DATE | L8: REF | M8: CODE | N8: DATE | O8: REF | P8: DATE | Q8: REF | R8: CODE
A9: 1 | B9: START UP HEAD (LAUNCHER) DETAILS FOR 48" BYPASS PIPELINE 3 & 4 (SUH-T1) | C9: 2171-2172-NN-0001 | D9: A | E9: 3 | F9: ='PIPELINE & CABLE'!F16 -> 44575 | G9: 04/11/2021 12/01/2022 | H9: CSE-2171-72-PMT-T-005 | I9: 44575 | J9: 2171-2172-NPCC-T-0879
D10: B | E10: 3 | G10: 44594 | H10: CSE-2171-72-PMT-T-006 | I10: 44594 | J10: 2171-2172-NPCC-T-0942
D11: C | E11: 3 | G11: 44666 | H11: CSE-2171-72-PMT-T-020 | I11: 44666 | J11: 2171-2172-NPCC-T-1175
A12: 2 | B12: START UP HEAD (LAUNCHER) DETAILS FOR 48" BYPASS PIPELINE 1 & 2 SEG-A & B (SUH-T2) | C12: 2171-2172-NN-0002 | D12: A | E12: 3 | F12: ='PIPELINE & CABLE'!F12 -> 44564 | G12: 04/11/2021 12/01/2022 | H12: CSE-2171-72-PMT-T-005 | I12: 44575 | J12: 2171-2172-NPCC-T-0879
D13: B | E13: 3 | G13: 44594 | H13: CSE-2171-72-PMT-T-006 | I13: 44594 | J13: 2171-2172-NPCC-T-0942
A14: 3 | B14: LAYDOWN HEAD (RECEIVER) DETAILS FOR 48" BYPASS PIPELINE 3 & 4 (LDH-T1) | C14: 2171-2172-NN-0003 | D14: A | E14: 3 | F14: =F9 -> 44575 | G14: 04/11/2021 12/01/2022 | H14: CSE-2171-72-PMT-T-005 | I14: 44575 | J14: 2171-2172-NPCC-T-0879
D15: B | E15: 3 | G15: 44594 | H15: CSE-2171-72-PMT-T-006 | I15: 44594 | J15: 2171-2172-NPCC-T-0942
D16: C | E16: 3 | G16: 44666 | H16: CSE-2171-72-PMT-T-020 | I16: 44666 | J16: 2171-2172-NPCC-T-1175
A17: 4 | B17: LAYDOWN HEAD (LAUNCHER) DETAILS FOR 48" BYPASS PIPELINE 1 & 2 SEG-A (LDH-T2) | C17: 2171-2172-NN-0004 | D17: A | E17: 3 | F17: =F12 -> 44564 | G17: 04/11/2021 12/01/2022 | H17: CSE-2171-72-PMT-T-005 | I17: 44575 | J17: 2171-2172-NPCC-T-0879
D18: B | E18: 3 | G18: 44594 | H18: CSE-2171-72-PMT-T-006 | I18: 44594 | J18: 2171-2172-NPCC-T-0942
D19: C | E19: 3 | G19: 44666 | H19: CSE-2171-72-PMT-T-020 | I19: 44666 | J19: 2171-2172-NPCC-T-1175
A20: 5 | B20: LAYDOWN HEAD (RECEIVER) DETAILS FOR 48" BYPASS PIPELINE 1 & 2 @ SEG-B (LDH-T3) | C20: 2171-2172-NN-0005 | D20: A | E20: 3 | F20: =F12 -> 44564 | G20: 04/11/2021 12/01/2022 | H20: CSE-2171-72-PMT-T-005 | I20: 44575 | J20: 2171-2172-NPCC-T-0879
D21: B | E21: 3 | G21: 44594 | H21: CSE-2171-72-PMT-T-006 | I21: 44594 | J21: 2171-2172-NPCC-T-0942
D22: C | E22: 3 | G22: 44666 | H22: CSE-2171-72-PMT-T-020 | I22: 44666 | J22: 2171-2172-NPCC-T-1175
A23: 6 | B23: EMERGENCY LAYDOWN HEAD FOR 48" BYPASS PIPELINES | C23: 2171-2172-NN-0006 | D23: A | E23: 3 | F23: =F12 -> 44564 | G23: 04/11/2021 12/01/2022 | H23: CSE-2171-72-PMT-T-005 | I23: 44575 | J23: 2171-2172-NPCC-T-0879
D24: B | E24: 3 | G24: 44594 | H24: CSE-2171-72-PMT-T-006 | I24: 44594 | J24: 2171-2172-NPCC-T-0942
A25: 7 | B25: LOADING ARRANGEMENT FOR TRANSPORTATION OF CONCRETE PIPE (CB-1) | C25: 2171-2172-NN-0007 | F25: ='PIPELINE & CABLE'!F25 -> 44564
A26: 8 | B26: LOADING ARRANGEMENT FOR TRANSPORTATION OF CONCRETE PIPE (CB-2) | C26: 2171-2172-NN-0008 | F26: ='PIPELINE & CABLE'!F26 -> 44595
A27: 9 | B27: LOADING ARRANGEMENT FOR TRANSPORTATION OF CONCRETE PIPE (CB-3) | C27: 2171-2172-NN-0009 | F27: 44623
A28: 10 | B28: LOADING ARRANGEMENT FOR TRANSPORTATION OF SUBSEA SPOOLS AND VALVE SKIDS (TRIP-1) | C28: 2171-2172-NN-0010 | F28: ='PIPELINE & CABLE'!F22 -> 44646
A29: 11 | B29: LOADING ARRANGEMENT FOR TRANSPORTATION OF SUBSEA SPOOLS AND VALVE SKIDS (TRIP-2) | C29: 2171-2172-NN-0011 | F29: ='PIPELINE & CABLE'!F23 -> 44654
A30: 12 | B30: LOADING ARRANGEMENT & SEAFASTENING DETAILS OF CONCRETE SLEEPERS @ CREST 287 | C30: 2171-2172-NN-0012 | D30: A | E30: 3 | F30: 44643 | G30: 44643 | H30: CSE-2171-72-PMT-T-015 | I30: 44648 | J30: 171-2172-NPCC-T-1099 | N30: 44648 | O30: 2171-2172-NPCC-MWS-T-0005 | P30: 44670 | Q30: BAS1178-TRN 007 | R30: comments
A31: 13 | B31: LOADING ARRANGEMENT & SEAFASTENING, DETAILS OF VALVE SKID, SPOOLS, SHROUDS & CONCRETE SLEEPERS FOR CFL-33 & CFL-35 @ EOS-283 | C31: 2171-2172-NN-0013 | D31: A | E31: 3 | F31: 44907 | G31: 44907 | H31: CSE-2171-72-PMT-T-041 | I31: 44908 | J31: 2171-2172-NPCC-T-1761 | N31: 44908 | O31: 2171-2172-NPCC-MWS-T-0022
D32: B | E32: 3 | G32: 44924 | H32: CSE-2171-72-PMT-T-050 | I32: 44924 | J32: 2171-2172-NPCC-T-1774 | N32: 44924 | O32: 2171-2172-NPCC-MWS-T-0030
D33: C | E33: 3 | G33: 45049 | H33: CSE-2171-72-PMT-T-062
A34: 14 | B34: LIFTING AND INSTALLATION OF 48" BYPASS PIPELINE-4 SPOOL G.A-2 FOR BYPASS PIPELINE-4 FOR CROSSING CFL35 PIPELINE | C34: 2171-2172-NN-0014 | D34: A | E34: 3 | F34: 44939 | G34: 44939 | H34: CSE-2171-72-PMT-T-056
A35: 15 | B35: LIFTING AND INSTALLATION OF 48" BYPASS PIPELINE-4 SPOOL G.A AT CLS 24 (JOP) | C35: 2171-2172-NN-0015 | D35: A | E35: 3 | G35: 44942 | H35: CSE-2171-72-PMT-T-057
A36: 16 | B36: LIFTING AND INSTALLATION OF 48" BYPASS PIPELINE-3 SPOOL G.A AT CFL36E (PLEM36 / SPM36) | C36: 2171-2172-NN-0016 | D36: A | E36: 3 | G36: 44944 | H36: CSE-2171-72-PMT-T-059
A37: 17 | B37: LIFTING AND INSTALLATION OF 48" BYPASS PIPELINE-4 SPOOL G.A AT CFL35E (PLEM35 / SPM35) | C37: 2171-2172-NN-0017 | D37: A | E37: 3 | G37: 44944 | H37: CSE-2171-72-PMT-T-058
A38: 18 | B38: LIFTING AND INSTALLATION OF 48" BYPASS PIPELINE SPOOL G.A FOR BYPASS P/L-2 AT CFL31W (PLEM31/SPM31) | C38: 2171-2172-NN-0018 | D38: A | E38: 3 | F38: =F34 -> 44939 | G38: 44935 | H38: CSE-2171-72-PMT-T-053 | I38: 44941 | J38: 2171-2172-NPCC-T-1786
A39: 19 | B39: LIFTING AND INSTALLATION OF 48" BYPASS PIPELINE FOR BYPASS P/L-2 FOR CROSSING CFL32 PIPELINE | C39: 2171-2172-NN-0019 | D39: A | E39: 3 | F39: =F35 -> 0 | G39: 44935 | H39: CSE-2171-72-PMT-T-053 | I39: 44941 | J39: 2171-2172-NPCC-T-1786
A40: 20 | B40: LIFTING AND INSTALLATION OF 48" BYPASS PIPELINE SPOOL G.A-2 FOR BYPASS P/L-2 NEAR CFL33W(PLEM33/SPM33) | C40: 2171-2172-NN-0020 | D40: A | F40: =F36 -> 0 | G40: 44931 | H40: CSE-2171-72-PMT-T-051 | I40: 44941 | J40: 2171-2172-NPCC-T-1786
...

Sheet SKETCHES
A1: Project 2171-2172
A2: SKETCHES
A3: CATEGORY : | G3: FORMAT | I3: Transmittal/Source | L3: REMARKS
A4: S.NO. | B4: PROJECT | C4: OFFSHORE DWG NO. | D4: TITLE/DESCRIPTION | E4: NO. OF SHEETS | F4: REV | G4: ACAD | H4: PDF | I4: Date | J4: Reference | K4: Location
A5: 1 | B5: 2171-2172 | C5: OFO-P2171-SK-001 | D5: SEA CONQUEST DECK LAYOUT | E5: 1 | F5: A | G5: √ | H5: √ | I5: 44467 | J5: HZD | K5: @
A6: 2 | B6: 2171-2172 | C6: OFO-P2171-SK-002 | D6: TYPICAL PIG LAUNCHER & RECEIVER PLAN | E6: 6 | F6: B | G6: √ | H6: √ | I6: 02/011/2021 | J6: AKS | K6: @
A7: 3 | B7: 2171-2172 | C7: OFO-P2171-SK-003 | D7: PROTECTOR DETAILS FOR DIA42", DIA48" & DIA56" PIPELINES DURING EXCAVATION PLANS | E7: 1 | F7: D | G7: √ | H7: √ | I7: 44485 | J7: REY | K7: @
A8: 4 | B8: 2171-2172 | C8: OFO-P2171-SK-004 | D8: SUPPORT FRAME FOR HTM/BISEP INSTALLTION OPERATION-SIT | E8: 2 + 48 | F8: FA, G | G8: √ | H8: √ | I8: 44718 | J8: HZD | K8: @
A9: 5 | B9: 2171-2172 | C9: OFO-P2171-SK-005 | D9: MOCK-UPASSEMBLY | E9: 11 | F9: C | G9: √ | H9: √ | I9: 44679 | J9: HZD | K9: @
A10: 6 | B10: 2171-2172 | C10: OFO-P2171-SK-006 | D10: DETAILS OF 56'' TEST FIXTURE SUPPORT | E10: 1 | F10: B,BA,C | G10: √ | H10: √ | I10: 44707 | J10: HZD | K10: @
A11: 7 | B11: 2171-2172 | C11: OFO-P2171-SK-007 | D11: WET SIT ASSEMBLY | E11: 10 | F11: C | G11: √ | H11: √ | I11: 44679 | J11: HZD | K11: @
A12: 8 | B12: 2171-2172 | C12: OFO-P2171-SK-008 | D12: DETAILS OF 48'' TEST FIXTURE SUPPORT | E12: 1 | F12: A,AA | G12: √ | H12: √ | I12: 44571 | J12: CDG | K12: @
A13: 9 | B13: 2171-2172 | C13: OFO-P2171-SK-009 | D13: DETAILS OF 42'' TEST FIXTURE SUPPORT | E13: 1 | F13: A,AA | G13: √ | H13: √ | I13: 44571 | J13: CDG | K13: @
A14: 10 | B14: 2171-2172 | C14: OFO-P2171-SK-010 | D14: 56'' HOT CLAMP ASSEMBLY LIFTING ARRANGEMENT | E14: 2 | F14: A | G14: √ | H14: √ | I14: 44574 | J14: HZD | K14: @
A15: 11 | B15: 2171-2172 | C15: OFO-P2171-SK-011 | D15: START-UP ARRANGEMENT PROPOSED 48" BYPASS P/L-1 (SEG-B) FROM CLS21(JOP) TIE-IN TO CFL32W(PLEM 32/SPM32) @ KP 1.016 | E15: 1 | F15: B | G15: √ | H15: √ | I15: 44669 | J15: REY | K15: @
A16: 12 | B16: 2171-2172 | C16: OFO-P2171-SK-012 | D16: START-UP ARRANGEMENT PROPOSED 48" BYPASS P/L-2 (SEG-B) FROM CLS22(JOP) TIE-IN TO CFL33W(PLEM 33/SPM33) & CFL31W(PLEM31/SPM31) @ KP 0.959 | E16: 1 | F16: B | G16: √ | H16: √ | I16: 44669 | J16: REY | K16: @
A17: 13 | B17: 2171-2172 | C17: OFO-P2171-SK-013 | D17: START-UP ARRANGEMENT PROPOSED 48" BYPASS P/L-2 (SEG-A) FROM CLS22(JOP) TIE-IN TO CFL33W(PLEM 33/SPM33) & CFL31W(PLEM31/SPM31) @ KP 0.933 | E17: 1 | F17: B | G17: √ | H17: √ | I17: 44669 | J17: REY | K17: @
A18: 14 | B18: 2171-2172 | C18: OFO-P2171-SK-014 | D18: START-UP ARRANGEMENT PROPOSED 48" BYPASS P/L-1 (SEG-A) FROM CLS21(JOP) TIE-IN TO CFL32W(PLEM 32/SPM32) @ KP 0.990 | E18: 1 | F18: B | G18: √ | H18: √ | I18: 44669 | J18: REY | K18: @
A19: 15 | B19: 2171-2172 | C19: OFO-P2171-SK-015 | D19: START-UP ARRANGEMENT PROPOSED 48" BYPASS P/L-3 FROM CLS23(JOP) TIE-IN TO CFL36W(PLEM 36/SPM36) @ KP 0.000 | E19: 1 | F19: B | G19: √ | H19: √ | I19: 44669 | J19: REY | K19: @
A20: 16 | B20: 2171-2172 | C20: OFO-P2171-SK-016 | D20: START-UP ARRANGEMENT PROPOSED 48" BYPASS P/L-4 FROM CLS24(JOP) TIE-IN TO CFL34W(PLEM 34/SPM34) & CFL35W(PLEM35/SPM35) @ KP 0.000 | E20: 1 | F20: B | G20: √ | H20: √ | I20: 44669 | J20: REY | K20: @
A21: 17 | B21: 2171-2172 | C21: OFO-P2171-SK-017 | D21: SUPPORT FRAME TYPE-2 FOR HTM/BISEP INSTALLTION OPERATION | E21: 2 | F21: A | G21: √ | H21: √ | I21: 44594 | J21: HZD | K21: @
A22: 18 | B22: 2171-2172 | C22: OFO-P2171-SK-018 | D22: HANDRAILS DETAILS FOR SUPPORT FRAME | E22: 2 + 19 | F22: D,DA | G22: √ | H22: √ | I22: 44621 | J22: HZD | K22: @
A23: 19 | B23: 2171-2172 | C23: OFO-P2171-SK-019 | D23: DETAILS OF 56'' FIXTURE SUPPORT TEST HEAD | E23: 1 + 3 | F23: A,AA,B | G23: √ | H23: √ | I23: 44617 | J23: CDG/HZD | K23: @
A24: 20 | B24: 2171-2172 | C24: OFO-P2171-SK-020 | D24: PROTECTOR DETAILS FOR PIPELINES DURING LAYING OF PL-3 & PL-4 | E24: 2 | F24: A | G24: √ | H24: √ | I24: 44606 | J24: NAR
A25: 21 | B25: 2171-2172 | C25: OFO-P2171-SK-021 | D25: DETAILS OF 56'' TEST FIXTURE SUPPORT - DRY SIT | J25: CDG
A26: 22 | B26: 2171-2172 | C26: OFO-P2171-SK-022 | D26: SUPPORT FRAME FOR HTM/BISEP INSTALLTION OPERATION | E26: 2 | F26: A | G26: √ | H26: √ | I26: 44594 | J26: HZD | K26: @
A27: 23 | B27: 2171-2172 | C27: OFO-P2171-SK-023 | D27: FRAME FOOTPRINT ARRANGEMENT | E27: 1 | F27: A | G27: √ | H27: √ | I27: 44595 | J27: HZD | K27: @
A28: 24 | B28: 2171-2172 | C28: OFO-P2171-SK-024 | D28: PROTECTOR DETAILS FOR PIPELINES DURING LAYING OF PL-1 & PL-2 (SEGMENT-B) | E28: 2 | F28: A | G28: √ | H28: √ | I28: 44606 | J28: CDG | L28: CANCELLED
A29: 25 | B29: 2171-2172 | C29: OFO-P2171-SK-025 | D29: PROTECTOR DETAILS FOR PIPELINES DURING LAYING OF PL-1 & PL-2 (SEGMENT-A) | E29: 2 | F29: A | G29: √ | H29: √ | I29: 44606 | J29: CDG | L29: CANCELLED
A30: 26 | B30: 2171-2172 | C30: OFO-P2171-SK-026 | D30: PROTECTOR DETAILS FOR PIPELINES DURING LAYING DOWN OF PL-3 & PL-4 | E30: 2 | F30: A | G30: √ | H30: √ | I30: 44606 | J30: CDG | L30: CANCELLED
A31: 27 | B31: 2171-2172 | C31: OFO-P2171-SK-027 | D31: GENERAL PIPELAY PROFILE | E31: 1 | F31: A | G31: √ | H31: √ | I31: 44603 | J31: HZD | K31: @
A32: 28 | B32: 2171-2172 | C32: OFO-P2171-SK-028 | D32: ABANDONMENT & RECOVERY ARRANGEMENT AT FINAL STAGE | E32: 1 | F32: A | G32: √ | H32: √ | I32: 44609 | J32: AKS
A33: 29 | B33: 2171-2172 | C33: OFO-P2171-SK-029 | D33: STINGER-10 SECTION-A 80" BUOYANCY TANK | E33: 1 | F33: A | G33: √ | H33: √ | I33: 44609 | J33: AKS
A34: 30 | B34: 2171-2172 | C34: OFO-P2171-SK-030 | D34: STINGER-9 SECTION-A 80" BUOYANCY TANK | E34: 1 | F34: A | G34: √ | H34: √ | I34: 44609 | J34: AKS
A35: 31 | B35: 2171-2172 | C35: OFO-P2171-SK-031 | D35: SPREADER BAR FRAME FOR BISEP | E35: 1 + 4 | F35: C,CA | G35: √ | H35: √ | I35: 44691 | J35: HZD | K35: @
A36: 32 | B36: 2171-2172 | C36: OFO-P2171-SK-032 | D36: ROV AND DIVING SPREAD FOOTPRINT ON DLS-750 | E36: 1 | F36: A | G36: √ | H36: √ | I36: 44624 | J36: HZD | K36: @
A37: 33 | B37: 2171-2172 | C37: OFO-P2171-SK-033 | D37: TYPICAL GRAVITY ANCHOR LIFTING ARRANGEMENT | E37: 1 | F37: A | G37: √ | H37: √ | I37: 44630 | J37: CDG | K37: @
A38: 34 | B38: 2171-2172 | C38: OFO-P2171-SK-034 | D38: SUPPORT FRAME-2 TYPE-1 FOR HTM/BISEP INSTALLATION OPERATION | E38: 2 + 48 | F38: B, BA | G38: √ | H38: √ | I38: 44719 | J38: HZD | K38: @
A39: 35 | B39: 2171-2172 | C39: OFO-P2171-SK-035 | D39: OFFSHORE INSTALLATION STEPS ASSEMBLY | E39: 7 | F39: D | G39: √ | H39: √ | I39: 44921 | J39: HZD | K39: @
A40: 36 | B40: 2171-2172 | C40: OFO-P2171-SK-036 | D40: TYPICAL LIFTING & HANDLING ARRANGEMENT FOR PIPE JOINTS BY DLB-750 | E40: 2 | F40: A | G40: √ | H40: √ | I40: 44650 | J40: AKS | K40: @
...
