Workbook

Sheet Data_List_Final_04
F1: Lower Zakum LTDP­1, EPC Works for EPS­2 and PDP Project
F2: PROJECT DELIVERABLES REGISTER
A3: COMPANY Project No. | F3: COMPANY DOC. No. AD-27-G-00915 | I3: REV
A4: 14001-11688
A5: CONTRACTOR Project No. | F5: CONTRACTOR DOC. No. 2745-PP-GE-001 | I5: 2
A6: 2745
A7: S/NO | B7: COMPANY DOCUMENT No. | C7: ID2 | D7: ID4 | E7: ID5 | F7: CONTRACTOR DOCUMENT No. | G7: TITLE / DESCRIPTION | H7: DOCUMENT CLASS | I7: PLANNED ISSUANCE DATE | J7: DOCUMENT CLASS
A8: 1 | B8: PROJECT GENERAL
A9: 1.1 | B9: AD-27-G-00915 | F9: 2745-PP-GE-001 | G9: PROJECT DELIVERABLES REGISTER
A10: 1.2 | B10: AD-27-G-00916 | F10: 2745-PP-GE-002 | G10: PROJECT EXECUTION PLAN
A11: 1.3 | B11: AD-27-G-00917 | F11: 2745-PP-GE-003 | G11: PROJECT COORDINATION PROCEDURE
A12: 1.4 | B12: AD-27-G-00918 | F12: 2745-PP-GE-004 | G12: DOCUMENT CONTROL PROCEDURE
A13: 1.5 | B13: AD-27-G-00919 | F13: 2745-PP-GE-005 | G13: PROJECT CONTROL PROCEDURE
A14: 1.6 | B14: AD-27-G-00920 | F14: 2745-PP-GE-006 | G14: PROJECT PLANNING PACKAGE
A15: 1.7 | B15: AD-27-G-00921 | F15: 2745-PP-GE-007 | G15: INVOICING PROCEDURE
A16: 1.8 | B16: AD-27-G-00922 | F16: 2745-PP-GE-008 | G16: 90 DAYS SCHEDULE
A17: 1.9 | B17: AD-27-G-00923 | F17: 2745-PP-GE-009 | G17: PROJECT CONTROLS CLOSE OUT REPORT
A18: 1.1 | B18: AD-27-G-00924 | F18: 2745-PP-GE-010 | G18: SUB-CONTRACT PROCEDURE
A19: 1.11 | B19: AD-27-G-00925 | F19: 2745-PP-GE-011 | G19: CHANGE MANAGEMENT PROCEDURE
A20: 1.12 | B20: AD-27-G-00926 | F20: 2745-PP-GE-012 | G20: FINAL DOSSIER INDEX
... A22: 1.14 | B22: AD-27-G-00928 | F22: 2745-PP-GE-014 | G22: RISK MANGEMENT PROCEDURE
B23: AD-27-G-02951 | F23: 2745-PP-GE-015 | G23: PROJECT RISK MANAGEMENT PLAN
A24: 1.16 | B24: AD-27-G-00929 | F24: 2745-PP-GE-016 | G24: PROJECT RISK REGISTER
A25: 1.17 | B25: AD-27-G-00930 | F25: 2745-PP-GE-017 | G25: INTERFACE MANAGEMENT PROCEDURE
A26: 1.18 | B26: AD-27-G-00931 | F26: 2745-PP-GE-018 | G26: INTERFACE REGISTER
A27: 1.19 | B27: AD-27-G-00932 | F27: 2745-PP-GE-019 | G27: LONG LEAD AND CERITICAL ITEMS LIST
A28: 1.2 | B28: AD-27-G-00933 | F28: 2745-PP-GE-020 | G28: SPARE PARTS DATA PACKAGE SUBMITTAL PLAN
A29: 1.21 | B29: AD-27-G-00934 | F29: 2745-PP-GE-021 | G29: TERMS OF REFERENCE FOR RISK MANAGEMENT WORKSHOP
A30: 1.22 | B30: AD-27-G-00935 | F30: 2745-PP-GE-022 | G30: TERMS OF REFERENCE FOR LESSON LEARNT WORKSHOP
B31: AD-27-G-02952 | F31: 2745-PP-GE-023 | G31: VENDOR DOCUMENTS MANAGMENT PROCEDURE
B32: AD-27-G-02953 | F32: 2745-PP-GE-024 | G32: SCOPE OF WORK FOR TRAINING COMPANY’S ENGINEERS
B33: AD-27-G-02954 | F33: 2745-PP-GE-025 | G33: POSITIVE MATERIAL IDENTIFICATION (PMI) SPECIFICATION
B34: AD-27-G-023004 | F34: 2745-PP-GE-026 | G34: PROJECT INTEGRITY PLAN
F35: 2745-PP-GE-027 | G35: PROJECT LESSONS LEARNED - MASTER REGISTER
F36: 2745-PP-GE-028 | G36: Fabrication Readiness Review Checklist for EPS-2 GO NO GO
F37: 2745-PP-GE-029 | G37: PROJECT MATERIAL MANAGEMENT PROCEDURE
F38: 2745-PP-GE-030 | G38: PROJECT SCHEDULE RISK ANALYSIS PROCEDURE
F39: 2745-PP-GE-031 | G39: PROJECT TARGET PLANNING PACKAGE
F40: 2745-PP-GE-032 | G40: METHOD STATEMENT FOR GROUT LINE HYDROTESTING
A43: 2 | B43: PROCUREMENT | K43: =IFERROR(VLOOKUP(C43,P6_Data!$B:$F,5,0),"") | L43: =IFERROR(VLOOKUP(D43,P6_Data!$B:$F,5,0),"") | M43: =IFERROR(VLOOKUP(E43,P6_Data!$B:$F,5,0),"")
...

Sheet PIPELINE & CABLE doc
D1: EPC FOR DALMA GAS DEVELOPMENT PROJECT PACKAGE-A (OFFSHORE FACILITIES) | O1: NPCC DOC. No.:
O2: CLIENT DOC. No. :
D3: NPCC PROJECT NO.8405 | O3: REVISION : | S3: 0
D4: OFFSHORE CONSTRUCTION ENGINEERING DOCUMENTS (PIPELINE & CABLE) | O4: DATE : | S4: 44363
A5: SR. NO. | B5: DESCRIPTION | C5: COMPANY DOCUMENT NUMBER | D5: NPCC DOCUMENT NUMBER | E5: REV. | F5: CLASS | G5: SUBMISSION PLANNED DATE | H5: NPCC | L5: CLIENT | O5: GMC | T5: REMARKS
H6: SUBMISSION STATUS | L6: APPROVAL STATUS | O6: SUBMISSION STATUS | Q6: APPROVAL STATUS
H7: CSE TO PMT | J7: PMT TO CLIENT | L7: FROM CLIENT | O7: PMT TO GMC | Q7: STATUS FROM GMC
H8: DATE | I8: REF | J8: DATE | K8: REF | L8: DATE | M8: REF | N8: CODE | O8: DATE | P8: REF | Q8: DATE | R8: REF | S8: CODE
A10: 1 | B10: PIPE STACKING ANALYSIS REPORT | C10: CF0000-32-REP-0001 | D10: 8405-NN-RP-001 | E10: A01 | F10: 1 | G10: 45048
A11: 2 | B11: PIPELAY ANALYSIS REPORT FOR PL-1 ( 16" GAS-CONDENSTAE) FROM SATAH WHP-10 TO ARZANAH ISLAND | C11: AZ0091-32-REP-0002 | D11: 8405-NN-RP-002 | E11: A01 | F11: 1 | G11: 45041
A12: 3 | B12: PIPELAY ANALYSIS REPORT FOR PL-2 ( 14" GAS-CONDENSTAE) FROM HD-3 TO HD WHP-T4 | C12: HD0201-32-REP-0003 | D12: 8405-NN-RP-003 | E12: A01 | F12: 1 | G12: 45044
A13: 4 | B13: PIPELAY ANALYSIS REPORT FOR PL-3 ( 18" GAS-CONDENSTAE) FROM HD WHP-T4 TO ARZANAH ISLAND | C13: AZ0091-32-REP-0004 | D13: 8405-NN-RP-004 | E13: A01 | F13: 1 | G13: 45050
A14: 5 | B14: PIPELAY ANALYSIS REPORT FOR PL-4 ( 18" GAS-CONDENSTAE) FROM WHP BH-3 SATAH WHP-10 TO ARZANAH ISLAND | C14: AZ0091-32-REP-0005 | D14: 8405-NN-RP-005 | E14: A01 | F14: 1 | G14: 45050
A15: 6 | B15: PIPELAY ANALYSIS REPORT FOR PL-5 ( 24" EXPORT GAS ) FROM ARZANAH ISLAND TO IGD-E(AT KP-38) | C15: KP3801-34-REP-0006 | D15: 8405-NN-RP-006 | E15: A01 | F15: 1 | G15: 45052
A16: 7 | B16: PIPELAY ANALYSIS REPORT FOR PL-6 ( 6" EXPORT-CONDENSTAE & FOC PIGGY BACKED) FROM ARZANAH ISLAND TO ZIRKU ISLAND | C16: AZ0091-32-REP-0007 | D16: 8405-NN-RP-007 | E16: A01 | F16: 1 | G16: 45053
A17: 8 | B17: SHORE PULL ANALYSES REPORT AT ARZANAH EAST | C17: AZ0091-32-REP-0008 | D17: 8405-NN-RP-008 | E17: A01 | F17: 1 | G17: 45028
A18: 9 | B18: SHORE PULL ANALYSES REPORT AT ARZANAH SOUTH | C18: AZ0091-32-REP-0009 | D18: 8405-NN-RP-009 | E18: A01 | F18: 1 | G18: 45029
A19: 10 | B19: SHORE PULL ANALYSIS REPORT AT ZIRKU ISLAND | C19: AZ0091-32-REP-0010 | D19: 8405-NN-RP-010 | E19: A01 | F19: 1 | G19: 45030
A20: 11 | B20: MIDLINE TIE-IN ANALYSIS REPORT | C20: CF0000-32-REP-0011 | D20: 8405-NN-RP-011 | E20: A01 | F20: 1 | G20: 45061
A21: 12 | B21: SEAFASTENING DESIGN REPORT FOR TRANSPORTATION OF CC PIPES ON CARGO BARGE | C21: CF0000-32-REP-0012 | D21: 8405-NN-RP-012 | E21: A01 | F21: 1 | G21: 45033
A22: 13 | B22: SEAFASTENING DESIGN REPORT FOR TRANSPORTATION OF CC PIPES ON CARGO BARGE | C22: Duplicate | D22: 8405-NN-RP-013 | E22: A01 | F22: 1 | G22: 45034
A23: 14 | B23: SEAFASTENING DESIGN REPORT FOR TRANSPORTATION OF CC PIPES ON CARGO BARGE | D23: 8405-NN-RP-014 | E23: A01 | F23: 1 | G23: 45035
A24: 15 | B24: SEAFASTENING DESIGN REPORT FOR TRANSPORTATION OF CC PIPES ON CARGO BARGE | D24: 8405-NN-RP-015 | E24: A01 | F24: 1 | G24: 45036
A25: 16 | B25: SEAFASTENING DESGIN REPORT FOR TRANSPORTATION OF CONCRETE SLEEPERS | D25: 8405-NN-RP-016 | E25: A01 | F25: 1 | G25: 45048
A26: 17 | B26: SEAFASTENING DESGIN REPORT FOR TRANSPORTATION OF CONCRETE SLEEPERS | D26: 8405-NN-RP-017 | E26: A01 | F26: 1 | G26: 45048
A27: 18 | B27: SEAFASTENING DESGIN REPORT FOR TRANSPORTATION OF CONCRETE SLEEPERS | D27: 8405-NN-RP-018 | E27: A01 | F27: 1 | G27: 45048
A28: 19 | B28: SEAFASTENING DESGIN REPORT FOR TRANSPORTATION OF CONCRETE SLEEPERS | D28: 8405-NN-RP-019 | E28: A01 | F28: 1 | G28: 45048
A29: 20 | B29: SEAFASTENING DESGIN REPORT FOR TRANSPORTATION OF CONCRETE MATTRESSES | D29: 8405-NN-RP-020 | E29: A01 | F29: 1 | G29: 45051
A30: 21 | B30: SEAFASTENING DESGIN REPORT FOR TRANSPORTATION OF CONCRETE MATTRESSES | D30: 8405-NN-RP-021 | E30: A01 | F30: 1 | G30: 45051
A31: 22 | B31: RISER/SPOOL LIFTING ANALYSIS REPORT AT WHP BH3 | C31: BH0101-32-REP-0013 | D31: 8405-NN-RP-022 | E31: A01 | F31: 1 | G31: 45097
A32: 23 | B32: RISER/SPOOL LIFTING ANALYSIS REPORT AT SATAH WHP-10 | C32: ST0101-32-REP-0014 | D32: 8405-NN-RP-023 | E32: A01 | F32: 1 | G32: 45058
A33: 24 | B33: RISER/SPOOL LIFTING ANALYSIS REPORT AT IGD-E | C33: KP3801-32-REP-0015 | D33: 8405-NN-RP-024 | E33: A01 | F33: 1 | G33: 45066
A34: 25 | B34: RISER/SPOOL LIFTING ANALYSIS REPORT AT WHP HD3 | C34: BH0101-32-REP-0016 | D34: 8405-NN-RP-025 | E34: A01 | F34: 1 | G34: 45097
A35: 26 | B35: RISER/SPOOL LIFTING ANALYSIS REPORT AT HD WHP-T4 | C35: BH0201-32-REP-0017 | D35: 8405-NN-RP-026 | E35: A01 | F35: 1 | G35: 45097
A36: 27 | B36: SEAFASTENING ANALYSIS REPORT FOR TRANSPORTATION OF SUBSEA SPOOLS (TRIP-1) | C36: CF0000-32-REP-0018 | D36: 8405-NN-RP-027 | E36: A01 | F36: 1 | G36: 45097
A37: 28 | B37: SEAFASTENING ANALYSIS REPORT FOR TRANSPORTATION OF SUBSEA SPOOLS (TRIP-2) | C37: CF0000-32-REP-0019 | D37: 8405-NN-RP-028 | E37: A01 | F37: 1 | G37: 45089
A38: 29 | B38: INSTALLATION ANALYSIS REPORT FOR CC-1( COMPOSITE CABLES FROM ARZANAH ISLAND TO IGD-E) | C38: KP3801-32-REP-0020 | D38: 8405-NN-RP-029 | E38: A01 | F38: 1 | G38: 45068
A39: 30 | B39: Composite Cable Installation analysis report | C39: CF0000-32-REP-0021 | D39: 8405-NN-RP-30 | E39: A01 | F39: 1 | G39: 45097
A40: 31 | B40: Umbilical Installation analysis report | C40: CF0000-32-REP-0022 | D40: 8405-NN-RP-31 | E40: A01 | F40: 1

Sheet Naval & Marine doc
D1: EPC FOR DALMA GAS DEVELOPMENT PROJECT PACKAGE-A (OFFSHORE FACILITIES) | O1: NPCC DOC. No.:
O2: CLIENT DOC. No. :
D3: NPCC PROJECT NO.8405 | O3: REVISION : | S3: 0
D4: OFFSHORE CONSTRUCTION ENGINEERING DOCUMENTS (PIPELINE & CABLE) | O4: DATE : | S4: 44277
A5: SR. NO. | B5: DESCRIPTION | C5: COMPANY DOCUMENT NUMBER | D5: NPCC DOCUMENT NUMBER | E5: REV. | F5: CLASS | G5: SUBMISSION PLANNED DATE | H5: NPCC | L5: CLIENT | O5: GMC | T5: REMARKS
H6: SUBMISSION STATUS | L6: APPROVAL STATUS | O6: SUBMISSION STATUS | Q6: APPROVAL STATUS
H7: CSE TO PMT | J7: PMT TO CLIENT | L7: FROM CLIENT | O7: PMT TO GMC | Q7: STATUS FROM GMC
H8: DATE | I8: REF | J8: DATE | K8: REF | L8: DATE | M8: REF | N8: CODE | O8: DATE | P8: REF | Q8: DATE | R8: REF | S8: CODE
A9: 1 | B9: STABILITY ANALYSIS DURING TRANSPORTATION OF CONCRETE COATED PIPEPIPE AT CARGO BAGE | C9: CF0000-32-REP-0021 | D9: 8405-ZZ-CL-001 | E9: A01 | F9: 1 | G9: 45049
A10: 2 | B10: STABILITY ANALYSIS DURING TRANSPORTATION OF CONCRETE COATED PIPEPIPE AT CARGO BAGE | C10: Duplicate | D10: 8405-ZZ-CL-002 | E10: A01 | F10: 1 | G10: 45049
A11: 3 | B11: STABILITY ANALYSIS DURING TRANSPORTATION OF CONCRETE COATED PIPEPIPE AT CARGO BAGE | D11: 8405-ZZ-CL-003 | E11: A01 | F11: 1 | G11: 45049
A12: 4 | B12: STABILITY ANALYSIS DURING TRANSPORTATION OF CONCRETE COATED PIPEPIPE AT CARGO BAGE | D12: 8405-ZZ-CL-004 | E12: A01 | F12: 1 | G12: 45049
A13: 5 | B13: STABILITY ANALYSIS DURING TRANSPORTATION OF CONCRETE SLEEPERS AT CARGO BAGE | D13: 8405-ZZ-CL-005 | E13: A01 | F13: 1 | G13: 45060
A14: 6 | B14: STABILITY ANALYSIS DURING TRANSPORTATION OF CONCRETE MATTRESS AT CARGO BAGE | C14: CF0000-32-REP-0022 | D14: 8405-ZZ-CL-006 | E14: A01 | F14: 1 | G14: 45060
A15: 7 | B15: STABILITY ANALYSIS DURING TRANSPORTATION OF CONCRETE SLEEPERS AT CARGO BAGE | C15: Duplicate | D15: 8405-ZZ-CL-007 | E15: A01 | F15: 1 | G15: 45060
A16: 8 | B16: MOORING ANALYSIS DURING LAYING PL-1 ( 16" GAS-CONDENSTAE) FROM SATAH WHP-10 TO ARZANAH ISLAND | C16: AZ0091-32-REP-0023 | D16: 8405-ZZ-CL-008 | E16: A01 | F16: 1 | G16: 45061
A17: 9 | B17: MOORING ANALYSIS DURING LAYING PL-2 ( 14" GAS-CONDENSTAE) FROM HD-3 TO HD WHP-T4 | C17: HD0201-32-REP-0024 | D17: 8405-ZZ-CL-009 | E17: A01 | F17: 1 | G17: 45062
A18: 10 | B18: MOORING ANALYSIS DURING LAYING PL-3 ( 18" GAS-CONDENSTAE) FROM HD WHP-T4 TO ARZANAH ISLAND | C18: AZ0091-32-REP-0025 | D18: 8405-ZZ-CL-010 | E18: A01 | F18: 1 | G18: 45063
A19: 11 | B19: MOORING ANALYSIS DURING LAYING PL-4 ( 18" GAS-CONDENSTAE) FROM WHP BH-3 SATAH WHP-10 TO ARZANAH ISLAND | C19: AZ0091-32-REP-0026 | D19: 8405-ZZ-CL-011 | E19: A01 | F19: 1 | G19: 45064
A20: 12 | B20: MOORING ANALYSIS DURING LAYING PL-5 ( 24" EXPORT GAS ) FROM ARZANAH ISLAND TO IGD-E(AT KP-38) | C20: KP3801-32-REP-0027 | D20: 8405-ZZ-CL-012 | E20: A01 | F20: 1 | G20: 45065
A21: 13 | B21: MOORING ANALYSIS DURING SHORE PULL AT ARZANAH EAST | C21: AZ0091-32-REP-0028 | D21: 8405-ZZ-CL-013 | E21: A01 | F21: 1 | G21: 45060
A22: 14 | B22: MOORING ANALYSIS DURING SHORE PULL AT ARZANAH SOUTH. | C22: AZ0091-32-REP-0029 | D22: 8405-ZZ-CL-014 | E22: A01 | F22: 1 | G22: 45026
A23: 15 | B23: MOORING ANALYSIS DURING SHORE PULL AT ZIRKU ISLAND | C23: AZ0091-32-REP-0030 | D23: 8405-ZZ-CL-015 | E23: A01 | F23: 1 | G23: 45026
A24: 16 | B24: MOORING ANALYSIS DURING MIDLINE TIE-IN | C24: CF0000-32-REP-0031 | D24: 8405-ZZ-CL-016 | E24: A01 | F24: 1 | G24: 45026
B25: MOORING ANALYSIS DURING MIDLINE TIE-IN | C25: CF0000-32-REP-0032 | D25: 8405-ZZ-CL-017 | E25: A01 | F25: 1 | G25: 45103
B26: MOORING ANALYSIS DURING LATERAL SHIFTING & STALK-ON RISER INSTALLATION FOR PL1 | C26: CF0000-32-REP-0033 | D26: 8405-ZZ-CL-018 | E26: A01 | F26: 1 | G26: 45085
B27: MOORING ANALYSIS DURING LATERAL SHIFTING & STALK-ON RISER INSTALLATION FOR PL2 | C27: CF0000-32-REP-0034 | D27: 8405-ZZ-CL-019 | E27: A01 | F27: 1 | G27: 45085
B28: MOORING ANALYSIS DURING LATERAL SHIFTING & STALK-ON RISER INSTALLATION FOR PL3 | C28: CF0000-32-REP-0035 | D28: 8405-ZZ-CL-020 | E28: A01 | F28: 1 | G28: 45085
B29: MOORING ANALYSIS DURING LATERAL SHIFTING & STALK-ON RISER INSTALLATION FOR PL4 | C29: CF0000-32-REP-0036 | D29: 8405-ZZ-CL-021 | E29: A01 | F29: 1 | G29: 45085
B30: MOORING ANALYSIS DURING LATERAL SHIFTING & STALK-ON RISER INSTALLATION FOR PL5 | C30: CF0000-32-REP-0037 | D30: 8405-ZZ-CL-022 | E30: A01 | F30: 1 | G30: 45085

Sheet DRAWINGS
D1: EPC FOR DALMA GAS DEVELOPMENT PROJECT PACKAGE-A (OFFSHORE FACILITIES) | O1: NPCC DOC. No.:
O2: CLIENT DOC. No. :
D3: NPCC PROJECT NO.8405 | O3: REVISION : | S3: 0
D4: OFFSHORE CONSTRUCTION ENGINEERING DOCUMENTS (PIPELINE & CABLE) | O4: DATE : | S4: 44277
A5: SR. NO. | B5: DESCRIPTION | C5: COMPANY DOCUMENT NUMBER | D5: NPCC DOCUMENT NUMBER | E5: REV. | F5: CLASS | G5: SUBMISSION PLANNED DATE | H5: NPCC | L5: CLIENT | O5: GMC | T5: REMARKS
H6: SUBMISSION STATUS | L6: APPROVAL STATUS | O6: SUBMISSION STATUS | Q6: APPROVAL STATUS
H7: CSE TO PMT | J7: PMT TO CLIENT | L7: FROM CLIENT | O7: PMT TO GMC | Q7: STATUS FROM GMC
H8: DATE | I8: REF | J8: DATE | K8: REF | L8: DATE | M8: REF | N8: CODE | O8: DATE | P8: REF | Q8: DATE | R8: REF | S8: CODE
A9: 1 | B9: SHOREPULL HEAD FOR PL-1( 16" GAS-CONDENSTAE FROM SATAH WHP-10 TO ARZANAH ISLAND ) | C9: AZ0091-32-LAY-0001 | D9: 8405-NN-0001 | E9: A01 | F9: 2 | G9: 45028
A10: 2 | B10: SHOREPULL HEAD FOR PL-4 ( 18" GAS-CONDENSTAE) FROM WHP BH-3 SATAH WHP-10 TO ARZANAH ISLAND | C10: AZ0091-32-LAY-0002 | D10: 8405-NN-0002 | E10: A01 | F10: 2 | G10: 45029
A11: 3 | B11: SHOREPULL HEAD FOR PL-6 ( ( 6" EXPORT-CONDENSTAE & FOC PIGGY BACKED) | C11: CF0000-32-LAY-0003 | D11: 8405-NN-0003 | E11: A01 | F11: 2 | G11: 45030
A12: 4 | B12: SHOREPULL HEAD FOR PL-5 ( 24" EXPORT GAS ) FROM ARZANAH ISLAND TO IGD-E(AT KP-38) | C12: KP3801-32-LAY-0004 | D12: 8405-NN-0004 | E12: A01 | F12: 2 | G12: 45031
A13: 5 | B13: SHOREPULL HEAD FOR PL-3 ( 18" GAS-CONDENSTAE) FROM HD WHP-T4 TO ARZANAH ISLAND | C13: AZ0091-32-LAY-0005 | D13: 8405-NN-0005 | E13: A01 | F13: 2 | G13: 45032
A14: 6 | B14: SHORE PULL HEAD FOR 24" CONDUIT | C14: CF0000-32-LAY-0006 | D14: 8405-NN-0006 | E14: A01 | F14: 2 | G14: 45033
A15: 7 | B15: SHORE PULL HEAD FOR 16" CONDUIT | C15: CF0000-32-LAY-0007 | D15: 8405-NN-0007 | E15: A01 | F15: 2 | G15: 45034
A16: 8 | B16: LAYDOWN HEAD FOR PL-1 ( 16" GAS-CONDENSTAE) | C16: CF0000-32-LAY-0008 | D16: 8405-NN-0008 | E16: A01 | F16: 2 | G16: 45028
A17: 9 | B17: LAYDOWN HEAD FOR PL-2 ( 14" GAS-CONDENSTAE) FROM HD-3 TO HD WHP-T4 | C17: HD0201-32-LAY-0009 | D17: 8405-NN-0009 | E17: A01 | F17: 2 | G17: 45029
A18: 10 | B18: LAYDOWN HEAD FOR PL-3 ( 18" GAS-CONDENSTAE) FROM HD WHP-T4 TO ARZANAH ISLAND | C18: AZ0091-32-LAY-0010 | D18: 8405-NN-0010 | E18: A01 | F18: 2 | G18: 45030
A19: 11 | B19: LAYDOWN HEAD FOR PL-4 ( 18" GAS-CONDENSTAE) FROM WHP BH-3 SATAH WHP-10 TO ARZANAH ISLAND | C19: AZ0091-32-LAY-0011 | D19: 8405-NN-0011 | E19: A01 | F19: 2 | G19: 45031
A20: 12 | B20: LAYDOWN HEAD FOR PL-5 ( 24" EXPORT GAS ) FROM ARZANAH ISLAND TO IGD-E(AT KP-38) | C20: KP3801-32-LAY-0012 | D20: 8405-NN-0012 | E20: A01 | F20: 2 | G20: 45032
... A84: 76 | B84: START UP HEAD DETAILS PL-2 (12" GAS-CONDENSATE) FROM HD-3 TO HD WHP-T4 | C84: HD0201-32-LAY-0075 | D84: 8405-NN-0076 | E84: A01 | F84: 1 | G84: 45088

Sheet Anchor Pattern
C1: ABU DHABI NATIONAL OIL COMPANY (ADNOC) EPC FOR DALMA GAS DEVELOPMENT PROJECT CONTRACT AGREEMENT NO: 6000001102(A)
A2: COMPANY Project No. | B2: P4331432 | C2: ANCHOR PATTERNS REGISTER | E2: Rev. 00
A3: CONTRACTOR Project No. | B3: 8405 | E3: =NOW() -> 45839.412
A4: Sl. No. | B4: Contractor Document No. | C4: COMPANY Document No. | D4: Title / Description | E4: Vessel Name | F4: Remarks | G4: REV. | H4: CLASS | I4: SUBMISSION PLANNED DATE
A5: 1 | B5: 8405-AP-0201 | C5: CF4901-34-LAY-0001 | D5: MUTAWA-101 ANCHOR PATTERN DURING JACKET FACE SURVEY AT WHP-10 | E5: MUTAWA-101 | F5: ISSUED | G5: A01 | H5: 1 | I5: 45168
A6: 2 | B6: 8405-AP-0202 | C6: BH4900-34-LAY-0002 | D6: MUTAWA-101 ANCHOR PATTERN DURING JACKET FACE SURVEY AT WHP-BH-3 | E6: MUTAWA-101 | F6: ISSUED | G6: A01 | H6: 1 | I6: 45168
A7: 3 | B7: 8405-AP-0203 | C7: HD4900-34-LAY-0003 | D7: MUTAWA-101 ANCHOR PATTERN DURING JACKET FACE SURVEY AT HD-3 | E7: MUTAWA-101 | F7: ISSUED | G7: A01 | H7: 1 | I7: 45168
A8: 4 | B8: 8405-AP-0204 | C8: CF0000-34-LAY-0004 | D8: MUTAWA-101 ANCHOR PATTERN DURING JACKET FACE SURVEY AT HD-WHP-T4 (EAST SIDE) | E8: MUTAWA-101 | F8: ISSUED | G8: A01 | H8: 1 | I8: 45168
A9: 5 | B9: 8405-AP-0205 | C9: CF0000-34-LAY-0005 | D9: MUTAWA-101 ANCHOR PATTERN DURING JACKET FACE SURVEY AT HD-WHP-T4 (WEST SIDE) | E9: MUTAWA-101 | F9: ISSUED | G9: A01 | H9: 1 | I9: 45168
A10: 6 | B10: 8405-AP-0206 | C10: KP0000-34-LAY-0006 | D10: MUTAWA-101 ANCHOR PATTERN DURING JACKET FACE SURVEY AT IGD-E | E10: MUTAWA-101 | F10: ISSUED | G10: A01 | H10: 1 | I10: 45107
A11: 7 | B11: 8405-AP-0001 | C11: ST0101-34-LAY-0001 | D11: ANCHOR PATTERN FOR BARGE DLB-750 DURING PIPELAY AND SHORE PULL OF PL-1 (14'' PIPELINE FROM SATAH WHP-10 TO ARZANAH ISLAND- EAST ) | E11: DLB-750 | G11: A01 | H11: 1 | I11: 45036
A12: 8 | B12: 8405-AP-0002 | C12: HD0101-34-LAY-0002 | D12: ANCHOR PATTERN FOR BARGE DLB-750 DURING PIPELAY OF PL-2 (12'' PIPELINE FROM HAIR DALMA HD-03 TO HAIR DALMA HD WHP-T4) | E12: DLB-750 | G12: A01 | H12: 1 | I12: 45038
A13: 9 | B13: 8405-AP-0003 | C13: HD0201-34-LAY-0003 | D13: ANCHOR PATTERN FOR BARGE DLB-750 DURING PIPELAY AND SHORE PULL OF PL-3 (16'' PIPELINE FROM HAIR DALMA HD WHP-T4 TO ARZANAH ISLAND- SOUTH) | E13: DLB-750 | G13: A01 | H13: 1 | I13: 45040
A14: 10 | B14: 8405-AP-0004 | C14: BH0091-34-LAY-0004 | D14: ANCHOR PATTERN FOR BARGE DLB-750 DURING PIPELAY AND SHORE PULL OF PL-4 (16'' PIPELINE FROM BU HASEER BH-03 TO ARZANAH ISLAND- EAST) | E14: DLB-750 | G14: A01 | H14: 1 | I14: 45042
A15: 11 | B15: 8405-AP-0005 | C15: KP0091-34-LAY-0005 | D15: ANCHOR PATTERN FOR BARGE DLB-750 DURING SHORE PULL AND PIPELAY OF PL-5 (24'' PIPELINE FROM ARZANAH ISLAND- EAST TO IGD-E) | E15: DLB-750 | G15: A01 | H15: 1 | I15: 45044
A16: 12 | B16: 8405-AP-0006 | C16: CF0091-34-LAY-0006 | D16: ANCHOR PATTERN FOR BARGE DLB-750 DURING SHORE PULL AND PIPELAY OF PL-6 (6'' PIPELINE FROM ARZANAH ISLAND- EAST TO ZIRKU ISLAND) | E16: DLB-750 | G16: A01 | H16: 1 | I16: 45046
A17: 13 | B17: 8405-AP-0007 | C17: KP0091-34-LAY-0007 | D17: ANCHOR PATTERN FOR BARGE DLB-750 DURING COMPOSITE CABLE SHORE PULL AND INSTALLATION OF CC-1 (FROM ARZANAH ISLAND- EAST TO IGD-E) | E17: DLB-750 | G17: A01 | H17: 1 | I17: 45048
A18: 14 | B18: 8405-AP-0008 | C18: ST0101-34-LAY-0008 | D18: ANCHOR PATTERN FOR BARGE DLB-750 DURING RISER INSTALLATION AT SATAH WHP-10 (14" RISER FOR (PL-1) PIPELINE FROM ARZANAH ISLAND TO SATAH WHP-10) | E18: DLB-750 | G18: A01 | H18: 1 | I18: 45050
A19: 15 | B19: 8405-AP-0009 | C19: HD0101-34-LAY-0009 | D19: ANCHOR PATTERN FOR BARGE SAFEEN-3000 DURING RISER INSTALLATION AT HD-03 (12" RISER FOR (PL-2) PIPELINE FROM HD-03 TO HD WHP-T4) | E19: SAFEEN-3000 | G19: A01 | H19: 1 | I19: 45052
A20: 16 | B20: 8405-AP-0010 | C20: HD0101-34-LAY-0010 | D20: ANCHOR PATTERN FOR BARGE SAFEEN-3000 DURING RISER INSTALLATION AT HD WHP-T4 (12" RISER FOR (PL-2) PIPELINE FROM HD-03 TO HD WHP-T4) | E20: SAFEEN-3000 | G20: A01 | H20: 1 | I20: 45054
A21: 17 | B21: 8405-AP-0011 | C21: AZ0091-34-LAY-0011 | D21: ANCHOR PATTERN FOR BARGE SAFEEN-3000 DURING RISER INSTALLATION AT HD WHP-T4 (16" RISER FOR (PL-3) PIPELINE FROM SOUTH ARZANAH ISLAND TO HD WHP-T4) | E21: SAFEEN-3000 | G21: A01 | H21: 1 | I21: 45056
A22: 18 | B22: 8405-AP-0012 | C22: BH0101-34-LAY-0012 | D22: ANCHOR PATTERN FOR BARGE SAFEEN-3000 DURING RISER INSTALLATION AT WHP BH-03 (16" RISER FOR (PL-4) PIPELINE FROM EAST ARZANAH ISLAND TO WHP BH-03) | E22: SAFEEN-3000 | G22: A01 | H22: 1
A23: 19 | B23: 8405-AP-0013 | C23: KP0091-34-LAY-0013 | D23: ANCHOR PATTERN FOR BARGE SAFEEN-3000 DURING RISER INSTALLATION AT IGD-E (KP-38) (24" RISER FOR (PL-5) PIPELINE FROM EAST ARZANAH ISLAND TO IGD-E (KP-38)) | E23: SAFEEN-3000 | G23: A01 | H23: 1
A24: 20 | B24: 8405-AP-0014 | C24: HD0091-34-LAY-0014 | D24: ANCHOR PATTERN FOR BARGE SAFEEN- 3000 DURING HD-03 JACKET EXTENSION | E24: SAFEEN-3000 | G24: A01 | H24: 1
A25: 21 | B25: 8405-AP-0015 | C25: HD0091-34-LAY-0015 | D25: ANCHOR PATTERN FOR BARGE DLB-750 DURING INSTALLATION OF 24" CONDUIT FOR UC-3 (UMBILICAL FROM ARZANAH ISLAND-SOUTH TO HD WHP-T4), AT ARZANAH ISLAND-SOUTH | E25: DLB-750 | G25: A01 | H25: 1
A26: 22 | B26: 8405-AP-0016 | C26: AZ0091-34-LAY-0016 | D26: ANCHOR PATTERN FOR BARGE DLB-750 DURING INSTALLATION OF 24" CONDUIT FOR UC-1 (UMBILICAL FROM ARZANAH ISLAND-EAST TO SATAH WHP-10), AT ARZANAH ISLAND-EAST | E26: DLB-750 | G26: A01 | H26: 1
A27: 23 | B27: 8405-AP-0017 | C27: ST0101-34-LAY-0017 | D27: ANCHOR PATTERN FOR BARGE DLB-750 DURING INSTALLATION OF 24" CONDUIT FOR UC-4 (UMBILICAL FROM ARZANAH ISLAND-EAST TO BH-3), AT ARZANAH ISLAND-EAST | E27: DLB-750 | G27: A01 | H27: 1 | I27: 45063
A28: 24 | B28: 8405-AP-0018 | C28: AZ0091-34-LAY-0018 | D28: ANCHOR PATTERN FOR BARGE DLB-750 DURING INSTALLATION OF 16" CONDUIT FOR CC-1 (COMPOSITE CABLE FROM ARZANAH ISLAND-EAST TO IGD-E), AT ARZANAH ISLAND-EAST | E28: DLB-750 | G28: A01 | H28: 1 | I28: 45063
A29: 25 | B29: 8405-AP-0101 | C29: HD0091-34-LAY-0101 | D29: ANCHOR PATTERN FOR BARGE SEP-450 DURING REMOVAL OF EXISTING TOPSIDE OF HAIR DALMA HD-03 | E29: SEP-450 | G29: A01 | H29: 1
A30: 26 | B30: 8405-AP-0102 | C30: HD0091-34-LAY-0102 | D30: ANCHOR PATTERN FOR BARGE SEP-450 DURING INSTALLATION OF NEW TOPSIDE FOR HAIR DALMA HD-03 | E30: SEP-450 | G30: A01 | H30: 1
A31: 27 | B31: 8405-AP-0103 | C31: HD0091-34-LAY-0103 | D31: ANCHOR PATTERN FOR BARGE SEP-450 DURING INSTALLATION OF HD WHP-T4 TOPSIDE | E31: SEP-450 | G31: A01 | H31: 1
A32: 28 | B32: 8405-AP-0104 | C32: BH0101-34-LAY-0104 | D32: ANCHOR PATTERN FOR BARGE SEP-450 DURING INSTALLATION OF WHP BH-03 TOPSIDE | E32: SEP-450 | G32: A01 | H32: 1
A33: 29 | B33: 8405-AP-0105 | C33: ST0101-34-LAY-0105 | D33: ANCHOR PATTERN FOR BARGE SEP-450 DURING INSTALLATION OF SATAH WHP-10 TOPSIDE | E33: SEP-450 | G33: A01 | H33: 1
A34: 30 | B34: 8405-AP-0106 | C34: KP0091-34-LAY-0106 | D34: ANCHOR PATTERN FOR BARGE SEP-750 DURING DECK EXTENSION AT IGD-E | E34: SEP-750 | G34: A01 | H34: 1

Sheet DP
C1: ABU DHABI NATIONAL OIL COMPANY (ADNOC) EPC FOR DALMA GAS DEVELOPMENT PROJECT CONTRACT AGREEMENT NO: 6000001102(A)
A2: COMPANY Project No. | B2: P4331432 | C2: DP SET- UP PLANS REGISTER | E2: Rev. 00
A3: CONTRACTOR Project No. | B3: 8405 | E3: 45026
A4: Sl. No. | B4: Contractor Document No. | C4: COMPANY Document No. | D4: Title / Description | E4: Vessel Name | F4: Remarks
A5: 1 | B5: 8405-DP-0201 | C5: ST0101-34-LAY-0201 | D5: DP SET- UP PLAN FOR UMBILICAL & CABLE LAYING VESSEL DURING UMBILICAL SHORE PULL AND INSTALLATION OF UC-1 (UMBILICAL FROM ARZANAH ISLAND-EAST TO SATAH WHP-10) | E5: UMBILICAL & CABLE LAYING VESSEL
A6: 2 | B6: 8405-DP-0202 | C6: HD0101-34-LAY-0202 | D6: DP SET- UP PLAN FOR UMBILIUMBILICAL & CABLE LAYING VESSEL DURING UMBILICAL INSTALLATION OF UC-2 (UMBILICAL FROM HD-03 TO HD WHP-T4) | E6: UMBILICAL & CABLE LAYING VESSEL
A7: 3 | B7: 8405-DP-0203 | C7: HD0101-34-LAY-0203 | D7: DP SET- UP PLAN FOR UMBILICAL & CABLE LAYING VESSEL DURING UMBILICAL SHORE PULL AND INSTALLATION OF UC-3 (UMBILICAL FROM ARZANAH ISLAND-SOUTH TO HD WHP-T4) | E7: UMBILICAL & CABLE LAYING VESSEL
A8: 4 | B8: 8405-DP-0204 | C8: BH0101-34-LAY-0204 | D8: DP SET- UP PLAN FOR UMBILICAL & CABLE LAYING VESSEL DURING UMBILICAL SHORE PULL AND INSTALLATION OF UC-4 (UMBILICAL FROM ARZANAH ISLAND-EAST TO BH-03) | E8: UMBILICAL & CABLE LAYING VESSEL
A9: 5 | B9: 8405-DP-0205 | C9: KP0091-34-LAY-0205 | D9: DP SET- UP PLAN FOR VESSEL SAFEEN PRINCE DURING J-TUBE INSTALLATION AT IGD-E (KP-38) (16" J-TUBE FOR (CC-1) COMPOSITE CABLE FROM EAST ARZANAH ISLAND (SPLITTER BOX) TO IGD-E (KP-38)) | E9: SAFEEN PRINCE
A10: 6 | B10: 8405-DP-0206 | C10: CF0000-34-LAY-0206 | D10: DP SET- UP PLAN FOR UMBILICAL & CABLE LAYING VESSEL WHILE AT VESSEL ACCESS CHANNEL | E10: UMBILICAL & CABLE LAYING VESSEL
A11: 7 | B11: 8405-DP-0207 | C11: ST0101-34-LAY-0207 | D11: DP SET- UP PLAN FOR UMBILICAL & CABLE LAYING VESSEL DURING UMBILICAL INSTALLATION OF UC-1 (UMBILICAL FROM ARZANAH ISLAND-EAST TO SATAH WHP-10), AT SHALLOW WATER AREA | E11: UMBILICAL & CABLE LAYING VESSEL
A12: 8 | B12: 8405-DP-0101 | C12: KP0091-34-LAY-0101 | D12: DP SET- UP PLAN FOR BARGE SEP-450 DURING DECK EXTENSION AT IGD-E | E12: SEP-450

Sheet COMMISSION  - List of OTP 
C1: OPERATIONAL TEST PROCEDURES LIST
C5: ADNOC Document No.: CA0000-54-PRO-003 | R5: Rev.
C8: CONTRACTOR Document No.: 8405-PP-CM-006 | R8: A
A11: OTPs / ALL PLATFORMS
A14: OTPs - PLATFORM : BH-03
A15: Project Document Number | B15: ADNOC Document Number | C15: System Number | D15: Rev | E15: Sub-Systems | L15: Title | M15: OTP | N15: Vendor Required | O15: Commissioning Phase | P15: Discipline Custodian | Q15: Location | R15: Remarks
A16: 8405-BH0091-100-0001 | B16: BH0091-54-PRO-100-0001 | C16: BH0091-100 | D16: A01 | E16: 001 | L16: OTP for BH-03 to Arzanah 16" Gas Producer Sebsea Pipeline | M16: X | N16: No | O16: Stage 5 | P16: Process | Q16: Offshore
A17: 8405-HB0101-110-0001 | B17: BH0101-54-PRO-110-0001 | C17: BH0101-110 | D17: A01 | E17: 001 | F17: 005 | G17: 007 | H17: 009 | L17: OTP for Wellhead Control Panel (WHCP) & Wellheads | M17: X | N17: Yes | O17: Stage 2 | P17: Instrumentation | Q17: Onshore / Offshore
C18: BH0101-610 | D18: A01 | E18: 001 | F18: 002
A19: 8405-BH0101-401-0001 | B19: BH0101-54-PRO-401-0001 | C19: BH0101-401 | D19: A01 | E19: 001 | F19: 002 | G19: 004 | L19: OTP for Production Manifold & MPFM | M19: X | N19: Yes | O19: Stage 4 | P19: Process/Instrumentation | Q19: Onshore / Offshore
A20: 8405-BH0101-501-0001 | B20: BH0101-54-PRO-501-0001 | C20: BH0101-501 | D20: A01 | E20: 001 | L20: OTP for Nitrogen Distribution | M20: X | N20: No | O20: Stage 3 | P20: Mechanical | Q20: Onshore
A21: 8405-BH0101-502-0001 | B21: BH0101-54-PRO-502-0001 | C21: BH0101-502 | D21: A01 | E21: 001 | F21: 002 | G21: 003 | H21: 004 | I21: 005 | J21: 006 | L21: OTP for Chemical Injection | M21: X | N21: No | O21: Stage 3 | P21: Mechanical | Q21: Onshore / Offshore
A22: 8405-BH0101-511-0001 | B22: BH0101-54-PRO-511-0001 | C22: BH0101-511 | D22: A01 | E22: 001 | F22: 002 | L22: OTP for Hazardous Open Drains | M22: X | N22: No | O22: Stage 3 | P22: Mechanical | Q22: Onshore
A23: 8405-BH0101-512-0001 | B23: BH0101-54-PRO-512-0001 | C23: BH0101-512 | D23: A01 | E23: 001 | F23: 002 | L23: OTP for Closed Drains | M23: X | N23: No | O23: Stage 3 | P23: Mechanical | Q23: Onshore
A24: 8405-BH0101-601-0001 | B24: BH0101-54-PRO-601-0001 | C24: BH0101-601 | D24: A01 | E24: 001 | F24: 002 | L24: OTP for DCS System | M24: X | N24: Yes | O24: Stage 2 | P24: Instrumentation | Q24: Onshore / Offshore
A25: 8405-BH0101-602-0001 | B25: BH0101-54-PRO-602-0001 | C25: BH0101-602 | D25: A01 | E25: 001 | F25: 002 | L25: OTP for ESD System and Cause & Effect | M25: X | N25: Yes | O25: Stage 2 | P25: Instrumentation | Q25: Onshore / Offshore
A26: 8405-BH0101-603-0001 | B26: BH0101-54-PRO-603-0001 | C26: BH0101-603 | D26: A01 | E26: 001 | F26: 002 | G26: 003 | L26: OTP for F&G System and Cause & Effect | M26: X | N26: Yes | O26: Stage 2 | P26: Instrumentation | Q26: Onshore / Offshore
A27: 8405-BH0101-620-0001 | B27: BH0101-54-PRO-620-0001 | C27: BH0101-620 | D27: A01 | E27: 001 | L27: OTP for HIPPS System | M27: X | N27: Yes | O27: Stage 2 | P27: Instrumentation | Q27: Onshore
A28: 8405-BH0101-652-0001 | B28: BH0101-54-PRO-652-0001 | C28: BH0101-652 | D28: A01 | E28: 001 | L28: OTP for Telephone & Tetra System | M28: X | N28: Yes | O28: Stage 4 | P28: Telecom | Q28: Onshore / Offshore
A29: 8405-BH0101-653-0001 | B29: BH0101-54-PRO-653-0001 | C29: BH0101-653 | D29: A01 | E29: 001 | L29: OTP for CCTV System | M29: X | N29: Yes | O29: Stage 4 | P29: Telecom | Q29: Onshore / Offshore
A30: 8405-BH0101-701-0001 | B30: BH0101-54-PRO-701-0001 | C30: BH0101-701 | D30: A01 | E30: 001 | F30: 002 | L30: OTP for Firefighting System | M30: X | N30: No | O30: Stage 3 | P30: Mechanical | Q30: Onshore
A31: 8405-BH0091-800-0001 | B31: BH0091-54-PRO-8000-0001 | C31: BH0091-800 | D31: A01 | E31: 001 | L31: OTP for BH-03 to Arzanah Subsea Umbilical | M31: X | N31: Yes | O31: Stage 5 | P31: Electrical | Q31: Offshore
C32: BH0091-810 | D32: A01 | E32: 001
C33: BH0091-811 | D33: A01 | E33: 001
A34: 8405-BH0101-820-0001 | B34: BH0101-54-PRO-820-0001 | C34: BH0101-820 | D34: A01 | E34: 001 | L34: OTP for 6.6 KV Ring Main Unit | M34: X | N34: Yes | O34: Stage 1 | P34: Electrical | Q34: Onshore / Offshore
A35: 8405-BH0101-821-0001 | B35: BH0101-54-PRO-821-0001 | C35: BH0101-821 | D35: A01 | E35: 001 | L35: OTP for 6.6 KV / 433 V Transformer | M35: X | N35: Yes | O35: Stage 1 | P35: Electrical | Q35: Onshore / Offshore
A36: 8405-BH0101-830-0001 | B36: BH0101-54-PRO-830-0001 | C36: BH0101-830 | D36: A01 | E36: 001 | F36: 002 | G36: 003 | H36: 004 | I36: 005 | J36: 006 | L36: OTP for 415 V Switchboard & Small Power | M36: X | N36: Yes | O36: Stage 1 | P36: Electrical | Q36: Onshore
A37: 8405-BH0101-840-0001 | B37: BH0101-54-PRO-840-0001 | C37: BH0101-840 | D37: A01 | E37: 001 | F37: 002 | L37: OTP for 24 V DC UPS | M37: X | N37: Yes | O37: Stage 1 | P37: Electrical | Q37: Onshore
A38: 8405-BH0101-850-0001 | B38: BH0101-54-PRO-850-0001 | C38: BH0101-850 | D38: A01 | E38: 001 | L38: OTP for Electrical Control & Monitoring System (ECMS) | M38: X | N38: Yes | O38: Stage 1 | P38: Electrical | Q38: Onshore / Offshore
A39: 8405-BH0101-860-0001 | B39: BH0101-54-PRO-860-0001 | C39: BH0101-860 | D39: A01 | E39: 001 | L39: OTP for Navaids System | M39: X | N39: No | O39: Stage 4 | P39: Electrical | Q39: Onshore
A40: 8405-BH0101-861-0001 | B40: BH0101-54-PRO-861-0001 | C40: BH0101-861 | D40: A01 | E40: 001 | L40: OTP for Bird Deterrent System | M40: X | N40: No | O40: Stage 4 | P40: Electrical | Q40: Onshore
A41: OTPs - PLATFORM : HD-03
A42: Project Document Number | B42: ADNOC Document Number | C42: System Number | D42: Rev | E42: Sub-Systems | L42: Title | M42: OTP | N42: Vendor Required | O42: Commissioning Phase | P42: Discipline Custodian | R42: Remarks
A43: 8405-HD0091-100-0001 | B43: HD0091-54-PRO-100-0001 | C43: HD0091-100 | D43: A01 | E43: 001 | L43: OTP for HD-03 to HD-T4 12" Gas Producer Sebsea Pipeline | M43: X | N43: No | O43: Stage 5 | P43: Process | Q43: Offshore
A44: 8405-HD0101-110-0001 | B44: HD0101-54-PRO-110-0001 | C44: HD0101-110 | D44: A01 | E44: 001 | F44: 009 | L44: OTP for Wellhead Control Panel (WHCP) & Wellheads | M44: X | N44: Yes | O44: Stage 2 | P44: Instrumentation | Q44: Onshore / Offshore
C45: HD0101-610 | D45: A01 | E45: 001 | F45: 002
A46: 8405-HD0101-401-0001 | B46: HD0101-54-PRO-401-0001 | C46: HD0101-401 | D46: A01 | E46: 001 | F46: 002 | G46: 004 | L46: OTP for Production Manifold & MPFM | M46: X | N46: Yes | O46: Stage 4 | P46: Process/Instrumentation | Q46: Onshore / Offshore
A47: 8405-HD0101-501-0001 | B47: HD0101-54-PRO-501-0001 | C47: HD0101-501 | D47: A01 | E47: 001 | L47: OTP for Nitrogen Distribution | M47: X | N47: No | O47: Stage 3 | P47: Mechanical | Q47: Onshore
A48: 8405-HD0101-502-0001 | B48: HD0101-54-PRO-502-0001 | C48: HD0101-502 | D48: A01 | E48: 001 | F48: 002 | G48: 004 | H48: 005 | I48: 006 | L48: OTP for Chemical Injection | M48: X | N48: No | O48: Stage 3 | P48: Mechanical | Q48: Onshore / Offshore
A49: 8405-HD0101-511-0001 | B49: HD0101-54-PRO-511-0001 | C49: HD0101-511 | D49: A01 | E49: 001 | F49: 002 | L49: OTP for Hazardous Open Drains | M49: X | N49: No | O49: Stage 3 | P49: Mechanical | Q49: Onshore
...

Sheet P6_List_Final
F1: EPC FOR DALMA GAS DEVELOPMENT PROJECT PACKAGE-A (OFFSHORE FACILITIES)
F2: PROJECT DELIVERABLES REGISTER
A3: COMPANY Project No. | F3: COMPANY DOC. No. CA0000-59-REG-0001 | I3: REV
A4: P4331432
A5: CONTRACTOR Project No. | F5: CONTRACTOR DOC. No. 8405-PP-GE-001 | I5: 01
A6: 8405
A7: SECTION | B7: COMPANY DOCUMENT No. | C7: ID2 | D7: ID4 | E7: ID5 | F7: CONTRACTOR DOCUMENT No. | G7: TITLE / DESCRIPTION | H7: DOCUMENT CLASS | I7: 1ST REVISION ISSUANCE PLANNED DATE | J7: ACTUAL DATE | K7: 2ND REVISION ISSUANCE PLANNED DATE | L7: ACTUAL DATE | M7: 3RD REVISION ISSUANCE PLANNED DATE | N7: ACTUAL DATE | O7: DOCUMENT CLASS
A8: A | B8: PROJECT MANAGEMENT
A9: A.1 | B9: PROJECT GENERAL
A10: A.1.1 | B10: CA0000-59-REG-0001 | C10: GDVPJ1000 | D10: GDVPJ1005 | E10: GDVPJ1010 | F10: 8405-PP-GE-001 | G10: PROJECT DELIVERABLES REGISTER | H10: 1 | I10: 44560 | J10: 44560 | K10: 44624 | M10: 44645 | O10: 1
A11: A.1.2 | B11: CA0000-59-PLN-0001 | C11: GDVPJ1015 | D11: GDVPJ1020 | E11: GDVPJ1025 | F11: 8405-PP-GE-002 | G11: PROJECT EXECUTION PLAN | H11: 1 | I11: 44573 | J11: 44572 | K11: 44601 | L11: 44595 | M11: 44643 | O11: 1
A12: A.1.3 | B12: CA0000-59-PRO-0001 | C12: GDVPJ1030 | D12: GDVPJ1035 | E12: GDVPJ1040 | F12: 8405-PP-GE-003 | G12: PROJECT COORDINATION & COMMUNICATION PROCEDURE | H12: 1 | I12: 44601 | J12: 44599 | K12: 44629 | M12: 44655 | O12: 1
A13: A.1.4 | B13: CA0000-59-PRO-0002 | C13: GDVPJ1045 | D13: GDVPJ1050 | E13: GDVPJ1055 | F13: 8405-PP-GE-004 | G13: PROJECT DOCUMENT CONTROL PROCEDURE | H13: 1 | I13: 44582 | J13: 44560 | K13: 44617 | L13: 44615 | M13: 44642 | O13: 1
A14: A.1.5 | B14: CA0000-59-PLN-0002 | C14: GDVPJ1060 | D14: GDVPJ1065 | E14: GDVPJ1070 | F14: 8405-PP-GE-005 | G14: PROJECT INTERFACE MANAGEMENT PLAN | H14: 2 | I14: 44603 | J14: 44572 | K14: 44624 | L14: 44608 | M14: 44642 | O14: 2
A15: A.1.6 | B15: CA0000-59-REG-0002 | C15: GDVPJ1090 | D15: GDVPJ1095 | E15: GDVPJ1100 | F15: 8405-PP-GE-006 | G15: PROJECT RISK REGISTER | H15: 2 | I15: 44643 | K15: 44649 | M15: 44662 | O15: 2
A16: A.1.7 | B16: CA0000-59-PRO-0011 | C16: GDVPT1065 | D16: GDVPT1075 | E16: GDVPT1085 | F16: 8405-PP-GE-007 | G16: VENDOR DOCUMENT MANAGEMENT PROCEDURE | H16: 1 | I16: 44692 | K16: 44727 | M16: 44760 | O16: 1
A17: A.1.8 | B17: CA0000-59-PRO-0004 | C17: GDVPJ1075 | D17: GDVPJ1080 | E17: GDVPJ1085 | F17: 8405-PP-GE-008 | G17: PROJECT RISK MANAGEMENT PROCEDURE | H17: 1 | I17: 44589 | J17: 44575 | K17: 44614 | L17: 44613 | M17: 44635 | O17: 1
A18: A.1.9 | B18: CA0000-50-REP-0002 | C18: GDVPJ1240 | D18: GDVPJ1245 | E18: GDVPJ1310 | F18: 8405-PP-GE-029 | G18: PROJECT RISK CLOSE-OUT REPORT | H18: 1 | I18: 45532 | K18: 45561 | M18: 45708 | O18: 1
A19: A.1.10 | B19: CA0000-50-PRO-0008 | F19: 8405-PP-GE-037 | G19: TOR / PROCEDURE FOR PROJECT RISK ASSESSMENT WORKSHOP | H19: 1 | I19: 44609 | O19: 1
A20: A.1.11 | B20: CA0000-59-PLN-0003 | C20: GDVPJ1105 | D20: GDVPJ1110 | E20: GDVPJ1115 | F20: 8405-PP-GE-009 | G20: PROJECT SUBCONTRACT PLAN | H20: 1 | I20: 44575 | J20: 44581 | K20: 44620 | M20: 44648 | O20: 1
A21: A.1.12 | B21: CA0000-59-PLN-0004 | C21: GDVPJ1120 | D21: GDVPJ1125 | E21: GDVPJ1130 | F21: 8405-PP-GE-010 | G21: ASSET INTEGRITY MANAGEMENT PLAN | H21: 1 | I21: 44631 | K21: 44673 | M21: 44706 | O21: 1
A22: A.1.13 | B22: CA0000-59-PRO-0005 | C22: GDVPJ1290 | D22: GDVPJ1300 | E22: GDVPJ1250 | F22: 8405-PP-GE-011 | G22: FINAL DOCUMENTATION HANDOVER PROCEDURE | H22: 1 | I22: 45187 | K22: 45216 | M22: 45244 | O22: 1
A23: A.1.14 | B23: CA0000-59-PRO-0006 | C23: GDVPJ1135 | D23: GDVPJ1140 | E23: GDVPJ1145 | F23: 8405-PP-GE-012 | G23: CONSTRUCTABILITY WORKSHOP PROCEDURE | H23: 1 | I23: 44732 | K23: 44760 | M23: 44791 | O23: 1
A24: A.1.15 | B24: CA0000-59-REP-0002 | F24: 8405-PP-GE-035 | G24: CONSTRUCTABILITY WORKSHOP REPORT | H24: 1 | I24: 44739 | O24: 1
A25: A.1.16 | B25: CA0000-59-REP-0003 | F25: 8405-PP-GE-036 | G25: CONSTRUCTABILITY WORKSHOP CLOSE-OUT REPORT | H25: 1 | I25: 44757 | O25: 1
A26: A.1.17 | B26: CA0000-59-PRO-0007 | C26: GDVPJ1150 | D26: GDVPJ1155 | E26: GDVPJ1160 | F26: 8405-PP-GE-013 | G26: PROJECT MATERIAL MANAGEMENT PROCEDURE | H26: 1 | I26: 44601 | J26: 44592 | K26: 44643 | M26: 44671 | O26: 1
A27: A.1.18 | B27: CA0000-59-REG-0003 | C27: GDVPJ1165 | D27: GDVPJ1170 | E27: GDVPJ1175 | F27: 8405-PP-GE-014 | G27: PROJECT INTERFACE REGISTER | H27: 2 | I27: 44589 | J27: 44582 | K27: 44617 | L27: 44636 | M27: 44649 | O27: 2
A28: A.1.19 | B28: CA0000-59-PRO-0008 | C28: GDVPJ1180 | D28: GDVPJ1185 | E28: GDVPJ1190 | F28: 8405-PP-GE-015 | G28: DESIGN DEVIATION / CONCESSION REQUEST AUTHORIZATION (DCA) PROCEDURE | H28: 1 | I28: 44608 | J28: 44596 | K28: 44631 | M28: 44652 | O28: 1
A29: A.1.20 | B29: CA0000-59-GDD-0001 | C29: GDVPJ1195 | D29: GDVPJ1200 | E29: GDVPJ1205 | F29: 8405-PP-GE-016 | G29: PROJECT PROCEDURE FOR NOTIFICATION TO SITE OF CHANGE (NSC) | H29: 1 | I29: 44608 | J29: 44606 | K29: 44629 | M29: 44650 | O29: 1
A30: A.1.21 | B30: CA0000-89-REP-0001 | F30: 8405-PP-GE-017 | G30: PROJECT CLOSE OUT REPORT | H30: 2 | I30: 44793 | O30: 2
A31: A.1.22 | B31: CA0000-59-COD-0001 | F31: 8405-PP-GE-038 | G31: PROJECT COMPLETION DOSSIER | H31: 1 | I31: 44793 | O31: 1
A32: A.1.23 | B32: CA0000-59-PRO-0009 | F32: 8405-PP-GE-039 | G32: AS-BUILT DOCUMENTATION PROCEDURE | H32: 1 | I32: 45347 | O32: 1
A33: A.1.24 | B33: CA0000-59-PLN-0005 | C33: GDVPJ1260 | D33: GDVPJ1270 | E33: GDVPJ1280 | F33: 8405-PP-GE-018 | G33: LOGISTICS MANAGEMENT PLAN | H33: 3 | I33: 44739 | K33: 44767 | M33: 44788 | O33: 3
A34: A.1.25 | B34: CA0000-50-PRO-0009 | F34: 8405-PP-GE-033 | G34: LESSON LEARNT PROCEDURE | H34: 1 | I34: 44593 | O34: 1
A35: A.1.26 | B35: CA0000-59-REG-0004 | C35: GDVPJ1210 | D35: GDVPJ1215 | E35: GDVPJ1220 | F35: 8405-PP-GE-019 | G35: LESSON LEARNT REGISTER | H35: 2 | I35: 44610 | K35: 44638 | M35: 44666 | O35: 2
A36: A.1.27 | B36: CA0000-89-REP-0002 | C36: GDVPJ1225 | D36: GDVPJ1230 | E36: GDVPJ1235 | F36: 8405-PP-GE-020 | G36: LESSON LEARNT WORKSHOP REPORT | H36: 2 | I36: 44671 | J36: 44617 | K36: 44699 | M36: 44727 | O36: 2
A37: A.1.28 | B37: CA0000-54-MAN-001 | F37: 8405-PP-CM-033 | G37: Operating Manuals (Various documents) | H37: 2 | I37: 45524 | O37: 2
A38: A.1.29 | B38: CA0000-54-MAN-002 | F38: 8405-PP-CM-034 | G38: INSTALLATION AND MAINTENANCE MANUALS (VARIOUS DOCUMENTS) | H38: 2 | I38: 45524 | O38: 2
A39: A.1.30 | B39: CA0000-59-MAN-001 | F39: 8405-PP-GE-040 | G39: CERTIFICATION MANUAL (THIS DOCUMENT ALREADY SEND THRU LETTER NO. 8405-NPCC-A-L-0059 DATED 22-02-22 | H39: 3 | I39: 44614 | O39: 3
A40: A.1.31 | B40: CA0000-59-MAN-002 | F40: 8405-PP-GE-041 | G40: INDEXES FOR FINAL DOCUMENTATION MANUALS | H40: 3 | I40: 45458 | O40: 3
...

Sheet P6_Data
A1: Activity Step Count | B1: Activity ID | C1: Activity Name | D1: Org Dur | E1: Early Start | F1: Early Finish | G1: Late Start | H1: Late Finish | I1: Total Float
A2: EPC FOR DALMA GAS DEVELOPMENT PROJECT | D2: 1159 | E2: 44549 | F2: 45708 | G2: 44549 | H2: 45738 | I2: 31
A3: MILESTONE | D3: 1159 | E3: 44549 | F3: 45708 | G3: 44549 | H3: 45738 | I3: 31
A4: PROJECT MILESTONES | D4: 1159 | E4: 44549 | F4: 45708 | G4: 44549 | H4: 45738 | I4: 31
A5: 0 | B5: MS1010 | C5: EFFECTIVE/COMMENCEMENT DATE | D5: 0 | E5: 44549 | G5: 44549 | I5: 0
A6: 0 | B6: MSGENA02 | C6: APPROVED PLANNING DOSSIER COVERING - BASELINE SCHEDULE, MILESTONE COMPLETION SCHEDULE, PROJECT CONTROL PROCEDURES ETC. | D6: 0 | F6: 44627 | H6: 44627 | I6: 0
A7: 0 | B7: MSCONF14 | C7: COMPLETION OF PRE- COMM & MC OF ALL PIPELINES INCL. COMPOSITE & FO CABLES | D7: 0 | F7: 45375 | H7: 45403 | I7: 28
A8: 0 | B8: MSCONF15 | C8: COMPLETION OF PRE- COMMISSIONING & MECHANICAL COMPLETION OF ALL UMBILICAL'S | D8: 0 | F8: 45383 | H8: 45403 | I8: 20
A9: 0 | B9: MSCONF16 | C9: COMPLETION OF PRE- COMM & MC OF ALL WHT'S (ST-10,HD-03, BH-03 & HD-T4) | D9: 0 | F9: 45389 | H9: 45433 | I9: 44
A10: 0 | B10: MS1070 | C10: M 1 - RFSU FOR OFFSHORE FACILITIES AT ST-10 | D10: 0 | F10: 45433 | H10: 45433 | I10: 0
A11: 0 | B11: MS1100 | C11: M 2 - RFSU FOR OFFSHORE FACILITIES AT BH-03 | D11: 0 | F11: 45433 | H11: 45433 | I11: 0
A12: 0 | B12: MS1060 | C12: M 3 - RFSU FOR OFFSHORE FACILITIES AT HD-03 | D12: 0 | F12: 45494 | H12: 45494 | I12: 0
A13: 0 | B13: MS1130 | C13: M 4 - RFSU FOR OFFSHORE FACILITIES AT HDT-04 | D13: 0 | F13: 45527 | H13: 45555 | I13: 28
A14: 0 | B14: MS2030 | C14: M 5 - COMPLETE TEST RUN & ACHIEVE PAC FOR ALL WHT'S PIPELINES & UMBILICAL | D14: 0 | F14: 45708 | H14: 45738 | I14: 31
A15: CONTRACTUAL COMPLETION MILESTONE | D15: 1119 | E15: 44589 | F15: 45708 | G15: 44680 | H15: 45738 | I15: 31
A16: GENERAL | D16: 138 | E16: 44655 | F16: 44854 | G16: 44762 | H16: 44993 | I16: 97
A17: 0 | B17: MSGENA01 | C17: ISSUE PROJECT EXECUTION PLAN, COORDINATION PROCEDURE, ENGG, PROCUREMENT PROCEDURES, HSE/QUALITY PLANS -FINAL ISSUE | D17: 0 | F17: 44655 | H17: 44762 | I17: 72
A18: 0 | B18: MSGENA03 | C18: ISSUE CONSTRUCTION EXECUTION PLAN/ PROCEDURES/ METHOD STATEMENTS ALONG WITH TIE-IN/ SHUTDOWN PHILOSOPHY, ETC | D18: 0 | F18: 44792 | H18: 44916 | I18: 87
A19: 0 | B19: MSGENA04 | C19: ISSUE HYDROTESTING, DRYING, PURGING, PRE-COMM, COMMISSIONING & DEMOLITION PROCEDURES - FINAL ISSUE | D19: 0 | F19: 44854 | H19: 44993 | I19: 97
A20: DETAIL ENGINEERING | D20: 246 | E20: 44589 | F20: 44945 | G20: 44701 | H20: 45043 | I20: 69
A21: 0 | B21: MSDEEB22 | C21: ISSUE IST MTO AND MRS FOR STRUCTURAL STEEL BULK MATERIALS FOR ALL AREAS. | D21: 0 | F21: 44589 | H21: 44764 | I21: 120
A22: 0 | B22: MSDEEB14 | C22: ISSUE IST MTO AND MRS FOR LINE PIPES | D22: 0 | F22: 44609 | H22: 44701 | I22: 64
A23: 0 | B23: MSDEEB15 | C23: ISSUE FINAL MTO AND MRS FOR LINE PIPES | D23: 0 | F23: 44655 | H23: 44714 | I23: 41
A24: 0 | B24: MSDEEB16 | C24: ISSUE IST MTO AND MRS FOR ALL BALANCE PIPELINE MATERIALS | D24: 0 | F24: 44670 | H24: 44824 | I24: 105
A25: 0 | B25: MSDEEB01 | C25: PREPARE DESIGN BASIS FOR ALL ENGINEERING DISCIPLINES AND ISSUE TO COMPANY - FINAL ISSUE | D25: 0 | F25: 44671 | H25: 44764 | I25: 62
A26: 0 | B26: MSDEEB18 | C26: ISSUE IST MTO AND MRS FOR ALL PIPING BULK MATERIALS | D26: 0 | F26: 44677 | H26: 44805 | I26: 87
A27: 0 | B27: MSDEEB05 | C27: COMPLETE 30% MODELLING FOR OFFSHORE FACILITIES | D27: 0 | F27: 44700 | H27: 44776 | I27: 52
A28: 0 | B28: MSDEEB02 | C28: PRE-ENGG SURVEY (TOPO/BATH/SOIL INVESTIGATION) & SUBMIT FINAL REPORTS, P/L ROUTE ALIGNMENT SHEETS & ROUTE MAPS (IFC) | D28: 0 | F28: 44700 | H28: 44790 | I28: 61
A29: 0 | B29: MSDEEB17 | C29: ISSUE FINAL MTO AND MRS FOR ALL BALANCE PIPELINE MATERIALS | D29: 0 | F29: 44701 | H29: 44809 | I29: 74
A30: 0 | B30: MSDEEB12 | C30: ISSUE MRS FOR ALL MECHANICAL EQUIPMENT & PACKAGES - FINAL | D30: 0 | F30: 44726 | H30: 44811 | I30: 59
A31: 0 | B31: MSDEEB04 | C31: ISSUE PFDS, P&IDS, PLOT PLANS, EQUIPMENT LAYOUTS AND EQUIPMENT LIST, FOR ALL FACILITIES FOR HAZOP | D31: 0 | F31: 44727 | H31: 44799 | I31: 50
A32: 0 | B32: MSDEEB13 | C32: ISSUE MRS FOR ALL E&I EQUIPMENT & PACKAGES - FINAL | D32: 0 | F32: 44728 | H32: 44811 | I32: 57
... A53: 0 | B53: MSDEEB30 | C53: COMPLETE ALL THE DETAIL ENGINEERING ACTIVITIES FOR OFFSHORE FACILITIES | D53: 0 | F53: 44945 | H53: 45043 | I53: 69
A54: PROCUREMENT | D54: 114 | E54: 44655 | F54: 44823 | G54: 44729 | H54: 44951 | I54: 91
A55: 0 | B55: MSPROC01 | C55: ISSUE PURCHASE ORDERS FOR LINE PIPES (COATED) | D55: 0 | F55: 44655 | H55: 44729 | I55: 52
A56: 0 | B56: MSPROC17 | C56: ISSUE PURCHASE ORDERS FOR ALL MAJOR CIVIL/ STRUCTURAL BULK MATERIALS - I MTO. | D56: 0 | F56: 44655 | H56: 44775 | I56: 81
A57: 0 | B57: MSPROC02 | C57: ISSUE PURCHASE ORDERS FOR LAUNCHERS AND RECEIVERS | D57: 0 | F57: 44701 | H57: 44769 | I57: 46
A58: 0 | B58: MSPROC03 | C58: ISSUE PURCHASE ORDER FOR PIPELINE HOT BENDS | D58: 0 | F58: 44701 | H58: 44827 | I58: 88
A59: 0 | B59: MSPROC04 | C59: ISSUE PURCHASE ORDERS FOR DRAIN DRUM & DRAIN PUMP | D59: 0 | F59: 44701 | H59: 44764 | I59: 43
A60: 0 | B60: MSPROC05 | C60: ISSUE PURCHASE ORDERS FOR PRESSURE VESSEL | D60: 0 | F60: 44701 | H60: 44764 | I60: 43
...

Sheet Data_List_Final_03
F1: EPC FOR DALMA GAS DEVELOPMENT PROJECT PACKAGE-A (OFFSHORE FACILITIES)
F2: PROJECT DELIVERABLES REGISTER
A3: COMPANY Project No. | F3: COMPANY DOC. No. CA0000-59-REG-0001 | I3: REV
A4: P4331432
A5: CONTRACTOR Project No. | F5: CONTRACTOR DOC. No. 8405-PP-GE-001 | I5: 03
A6: 8405
A7: SECTION | B7: COMPANY DOCUMENT No. | C7: ID2 | D7: ID4 | E7: ID5 | F7: CONTRACTOR DOCUMENT No. | G7: TITLE / DESCRIPTION | H7: DOCUMENT CLASS | I7: PLANNED ISSUANCE DATE | J7: DOCUMENT CLASS
A8: A | B8: PROJECT MANAGEMENT | N8: =MIN(N10:N275) -> -56 | O8: =MIN(O10:O275) -> 0 | P8: =MIN(P10:P275) -> 0
A9: A.1 | B9: PROJECT GENERAL | N9: =MAX(N10:N275) -> 48 | O9: =MAX(O10:O275) -> 0 | P9: =MAX(P10:P275) -> 0
A10: A.1.1 | B10: CA0000-59-REG-0001 | C10: GDVPJ1000 | D10: GDVPJ1005 | E10: GDVPJ1010 | F10: 8405-PP-GE-001 | G10: PROJECT DELIVERABLES REGISTER | H10: 1 | I10: 44560 | J10: 1 | K10: =IFERROR(VLOOKUP(C10,P6_Data!$B:$F,5,0),"") -> 44560 | L10: =IFERROR(VLOOKUP(D10,P6_Data!$B:$F,5,0),"") -> 44624 | M10: =IFERROR(VLOOKUP(E10,P6_Data!$B:$F,5,0),"") -> 44645 | N10: =IFERROR(K10-I10,0) -> 0 | O10: =IFERROR(L10-#REF!,0) -> 0 | P10: =IFERROR(M10-#REF!,0) -> 0
A11: A.1.2 | B11: CA0000-59-PLN-0001 | C11: GDVPJ1015 | D11: GDVPJ1020 | E11: GDVPJ1025 | F11: 8405-PP-GE-002 | G11: PROJECT EXECUTION PLAN | H11: 1 | I11: 44573 | J11: 1 | K11: =IFERROR(VLOOKUP(C11,P6_Data!$B:$F,5,0),"") -> 44573 | L11: =IFERROR(VLOOKUP(D11,P6_Data!$B:$F,5,0),"") -> 44601 | M11: =IFERROR(VLOOKUP(E11,P6_Data!$B:$F,5,0),"") -> 44643 | N11: =IFERROR(K11-I11,0) -> 0 | O11: =IFERROR(L11-#REF!,0) -> 0 | P11: =IFERROR(M11-#REF!,0) -> 0
A12: A.1.3 | B12: CA0000-59-PRO-0001 | C12: GDVPJ1030 | D12: GDVPJ1035 | E12: GDVPJ1040 | F12: 8405-PP-GE-003 | G12: PROJECT COORDINATION & COMMUNICATION PROCEDURE | H12: 1 | I12: 44601 | J12: 1 | K12: =IFERROR(VLOOKUP(C12,P6_Data!$B:$F,5,0),"") -> 44601 | L12: =IFERROR(VLOOKUP(D12,P6_Data!$B:$F,5,0),"") -> 44629 | M12: =IFERROR(VLOOKUP(E12,P6_Data!$B:$F,5,0),"") -> 44655 | N12: =IFERROR(K12-I12,0) -> 0 | O12: =IFERROR(L12-#REF!,0) -> 0 | P12: =IFERROR(M12-#REF!,0) -> 0
A13: A.1.4 | B13: CA0000-59-PRO-0002 | C13: GDVPJ1045 | D13: GDVPJ1050 | E13: GDVPJ1055 | F13: 8405-PP-GE-004 | G13: PROJECT DOCUMENT CONTROL PROCEDURE | H13: 1 | I13: 44582 | J13: 1 | K13: =IFERROR(VLOOKUP(C13,P6_Data!$B:$F,5,0),"") -> 44582 | L13: =IFERROR(VLOOKUP(D13,P6_Data!$B:$F,5,0),"") -> 44617 | M13: =IFERROR(VLOOKUP(E13,P6_Data!$B:$F,5,0),"") -> 44642 | N13: =IFERROR(K13-I13,0) -> 0 | O13: =IFERROR(L13-#REF!,0) -> 0 | P13: =IFERROR(M13-#REF!,0) -> 0
A14: A.1.5 | B14: CA0000-59-PLN-0002 | C14: GDVPJ1060 | D14: GDVPJ1065 | E14: GDVPJ1070 | F14: 8405-PP-GE-005 | G14: PROJECT INTERFACE MANAGEMENT PLAN | H14: 2 | I14: 44603 | J14: 2 | K14: =IFERROR(VLOOKUP(C14,P6_Data!$B:$F,5,0),"") -> 44603 | L14: =IFERROR(VLOOKUP(D14,P6_Data!$B:$F,5,0),"") -> 44624 | M14: =IFERROR(VLOOKUP(E14,P6_Data!$B:$F,5,0),"") -> 44642 | N14: =IFERROR(K14-I14,0) -> 0 | O14: =IFERROR(L14-#REF!,0) -> 0 | P14: =IFERROR(M14-#REF!,0) -> 0
A15: A.1.6 | B15: CA0000-59-REG-0002 | C15: GDVPJ1090 | D15: GDVPJ1095 | E15: GDVPJ1100 | F15: 8405-PP-GE-006 | G15: PROJECT RISK REGISTER | H15: 2 | I15: 44615 | J15: 2 | K15: =IFERROR(VLOOKUP(C15,P6_Data!$B:$F,5,0),"") -> 44631 | L15: =IFERROR(VLOOKUP(D15,P6_Data!$B:$F,5,0),"") -> 44649 | M15: =IFERROR(VLOOKUP(E15,P6_Data!$B:$F,5,0),"") -> 44662 | N15: =IFERROR(K15-I15,0) -> 16 | O15: =IFERROR(L15-#REF!,0) -> 0 | P15: =IFERROR(M15-#REF!,0) -> 0
A16: A.1.7 | B16: CA0000-59-PRO-0011 | C16: GDVPT1065 | D16: GDVPT1075 | E16: GDVPT1085 | F16: 8405-PP-GE-007 | G16: VENDOR DOCUMENT MANAGEMENT PROCEDURE | H16: 1 | I16: 44692 | J16: 1 | K16: =IFERROR(VLOOKUP(C16,P6_Data!$B:$F,5,0),"") -> 44699 | L16: =IFERROR(VLOOKUP(D16,P6_Data!$B:$F,5,0),"") -> 44727 | M16: =IFERROR(VLOOKUP(E16,P6_Data!$B:$F,5,0),"") -> 44760 | N16: =IFERROR(K16-I16,0) -> 7 | O16: =IFERROR(L16-#REF!,0) -> 0 | P16: =IFERROR(M16-#REF!,0) -> 0
A17: A.1.8 | B17: CA0000-59-PRO-0004 | C17: GDVPJ1075 | D17: GDVPJ1080 | E17: GDVPJ1085 | F17: 8405-PP-GE-008 | G17: PROJECT RISK MANAGEMENT PROCEDURE | H17: 1 | I17: 44589 | J17: 1 | K17: =IFERROR(VLOOKUP(C17,P6_Data!$B:$F,5,0),"") -> 44589 | L17: =IFERROR(VLOOKUP(D17,P6_Data!$B:$F,5,0),"") -> 44614 | M17: =IFERROR(VLOOKUP(E17,P6_Data!$B:$F,5,0),"") -> 44635 | N17: =IFERROR(K17-I17,0) -> 0 | O17: =IFERROR(L17-#REF!,0) -> 0 | P17: =IFERROR(M17-#REF!,0) -> 0
A18: A.1.9 | B18: CA0000-50-REP-0002 | C18: GDVPJ1240 | D18: GDVPJ1245 | E18: GDVPJ1310 | F18: 8405-PP-GE-029 | G18: PROJECT RISK CLOSE-OUT REPORT | H18: 1 | I18: 45532 | J18: 1 | K18: =IFERROR(VLOOKUP(C18,P6_Data!$B:$F,5,0),"") -> 45532 | L18: =IFERROR(VLOOKUP(D18,P6_Data!$B:$F,5,0),"") -> 45561 | M18: =IFERROR(VLOOKUP(E18,P6_Data!$B:$F,5,0),"") -> 45708 | N18: =IFERROR(K18-I18,0) -> 0 | O18: =IFERROR(L18-#REF!,0) -> 0 | P18: =IFERROR(M18-#REF!,0) -> 0
A19: A.1.10 | B19: CA0000-50-PRO-0008 | F19: 8405-PP-GE-037 | G19: TOR / PROCEDURE FOR PROJECT RISK ASSESSMENT WORKSHOP | H19: 1 | I19: 44609 | J19: 1 | K19: =IFERROR(VLOOKUP(C19,P6_Data!$B:$F,5,0),"") | L19: =IFERROR(VLOOKUP(D19,P6_Data!$B:$F,5,0),"") | M19: =IFERROR(VLOOKUP(E19,P6_Data!$B:$F,5,0),"") | N19: =IFERROR(K19-I19,0) -> 0 | O19: =IFERROR(L19-#REF!,0) -> 0 | P19: =IFERROR(M19-#REF!,0) -> 0
A20: A.1.11 | B20: CA0000-59-PLN-0003 | C20: GDVPJ1105 | D20: GDVPJ1110 | E20: GDVPJ1115 | F20: 8405-PP-GE-009 | G20: PROJECT SUBCONTRACT PLAN | H20: 1 | I20: 44575 | J20: 1 | K20: =IFERROR(VLOOKUP(C20,P6_Data!$B:$F,5,0),"") -> 44578 | L20: =IFERROR(VLOOKUP(D20,P6_Data!$B:$F,5,0),"") -> 44620 | M20: =IFERROR(VLOOKUP(E20,P6_Data!$B:$F,5,0),"") -> 44648 | N20: =IFERROR(K20-I20,0) -> 3 | O20: =IFERROR(L20-#REF!,0) -> 0 | P20: =IFERROR(M20-#REF!,0) -> 0
A21: A.1.12 | B21: CA0000-59-PLN-0004 | C21: GDVPJ1120 | D21: GDVPJ1125 | E21: GDVPJ1130 | F21: 8405-PP-GE-010 | G21: ASSET INTEGRITY MANAGEMENT PLAN | H21: 1 | I21: 44631 | J21: 1 | K21: =IFERROR(VLOOKUP(C21,P6_Data!$B:$F,5,0),"") -> 44638 | L21: =IFERROR(VLOOKUP(D21,P6_Data!$B:$F,5,0),"") -> 44673 | M21: =IFERROR(VLOOKUP(E21,P6_Data!$B:$F,5,0),"") -> 44706 | N21: =IFERROR(K21-I21,0) -> 7 | O21: =IFERROR(L21-#REF!,0) -> 0 | P21: =IFERROR(M21-#REF!,0) -> 0
A22: A.1.13 | B22: CA0000-59-PRO-0005 | C22: GDVPJ1290 | D22: GDVPJ1300 | E22: GDVPJ1250 | F22: 8405-PP-GE-011 | G22: FINAL DOCUMENTATION HANDOVER PROCEDURE | H22: 1 | I22: 45187 | J22: 1 | K22: =IFERROR(VLOOKUP(C22,P6_Data!$B:$F,5,0),"") -> 45187 | L22: =IFERROR(VLOOKUP(D22,P6_Data!$B:$F,5,0),"") -> 45216 | M22: =IFERROR(VLOOKUP(E22,P6_Data!$B:$F,5,0),"") -> 45244 | N22: =IFERROR(K22-I22,0) -> 0 | O22: =IFERROR(L22-#REF!,0) -> 0 | P22: =IFERROR(M22-#REF!,0) -> 0
A23: A.1.14 | B23: CA0000-59-PRO-0006 | C23: GDVPJ1135 | D23: GDVPJ1140 | E23: GDVPJ1145 | F23: 8405-PP-GE-012 | G23: CONSTRUCTABILITY WORKSHOP PROCEDURE | H23: 1 | I23: 44732 | J23: 1 | K23: =IFERROR(VLOOKUP(C23,P6_Data!$B:$F,5,0),"") -> 44727 | L23: =IFERROR(VLOOKUP(D23,P6_Data!$B:$F,5,0),"") -> 44760 | M23: =IFERROR(VLOOKUP(E23,P6_Data!$B:$F,5,0),"") -> 44791 | N23: =IFERROR(K23-I23,0) -> -5 | O23: =IFERROR(L23-#REF!,0) -> 0 | P23: =IFERROR(M23-#REF!,0) -> 0
A24: A.1.15 | B24: CA0000-59-REP-0002 | F24: 8405-PP-GE-035 | G24: CONSTRUCTABILITY WORKSHOP REPORT | H24: 1 | I24: 44739 | J24: 1 | K24: =IFERROR(VLOOKUP(C24,P6_Data!$B:$F,5,0),"") | L24: =IFERROR(VLOOKUP(D24,P6_Data!$B:$F,5,0),"") | M24: =IFERROR(VLOOKUP(E24,P6_Data!$B:$F,5,0),"") | N24: =IFERROR(K24-I24,0) -> 0 | O24: =IFERROR(L24-#REF!,0) -> 0 | P24: =IFERROR(M24-#REF!,0) -> 0
A25: A.1.17 | B25: CA0000-59-PRO-0007 | C25: GDVPJ1150 | D25: GDVPJ1155 | E25: GDVPJ1160 | F25: 8405-PP-GE-013 | G25: PROJECT MATERIAL MANAGEMENT PROCEDURE | H25: 1 | I25: 44601 | J25: 1 | K25: =IFERROR(VLOOKUP(C25,P6_Data!$B:$F,5,0),"") -> 44601 | L25: =IFERROR(VLOOKUP(D25,P6_Data!$B:$F,5,0),"") -> 44643 | M25: =IFERROR(VLOOKUP(E25,P6_Data!$B:$F,5,0),"") -> 44671 | N25: =IFERROR(K25-I25,0) -> 0 | O25: =IFERROR(L25-#REF!,0) -> 0 | P25: =IFERROR(M25-#REF!,0) -> 0
A26: A.1.18 | B26: CA0000-59-REG-0003 | C26: GDVPJ1165 | D26: GDVPJ1170 | E26: GDVPJ1175 | F26: 8405-PP-GE-014 | G26: PROJECT INTERFACE REGISTER | H26: 2 | I26: 44589 | J26: 2 | K26: =IFERROR(VLOOKUP(C26,P6_Data!$B:$F,5,0),"") -> 44589 | L26: =IFERROR(VLOOKUP(D26,P6_Data!$B:$F,5,0),"") -> 44617 | M26: =IFERROR(VLOOKUP(E26,P6_Data!$B:$F,5,0),"") -> 44649 | N26: =IFERROR(K26-I26,0) -> 0 | O26: =IFERROR(L26-#REF!,0) -> 0 | P26: =IFERROR(M26-#REF!,0) -> 0
A27: A.1.19 | B27: CA0000-59-PRO-0008 | C27: GDVPJ1180 | D27: GDVPJ1185 | E27: GDVPJ1190 | F27: 8405-PP-GE-015 | G27: DESIGN DEVIATION / CONCESSION REQUEST AUTHORIZATION (DCA) PROCEDURE | H27: 1 | I27: 44608 | J27: 1 | K27: =IFERROR(VLOOKUP(C27,P6_Data!$B:$F,5,0),"") -> 44608 | L27: =IFERROR(VLOOKUP(D27,P6_Data!$B:$F,5,0),"") -> 44631 | M27: =IFERROR(VLOOKUP(E27,P6_Data!$B:$F,5,0),"") -> 44652 | N27: =IFERROR(K27-I27,0) -> 0 | O27: =IFERROR(L27-#REF!,0) -> 0 | P27: =IFERROR(M27-#REF!,0) -> 0
A28: A.1.20 | B28: CA0000-59-GDD-0001 | C28: GDVPJ1195 | D28: GDVPJ1200 | E28: GDVPJ1205 | F28: 8405-PP-GE-016 | G28: PROJECT PROCEDURE FOR NOTIFICATION TO SITE OF CHANGE (NSC) | H28: 1 | I28: 44608 | J28: 1 | K28: =IFERROR(VLOOKUP(C28,P6_Data!$B:$F,5,0),"") -> 44608 | L28: =IFERROR(VLOOKUP(D28,P6_Data!$B:$F,5,0),"") -> 44629 | M28: =IFERROR(VLOOKUP(E28,P6_Data!$B:$F,5,0),"") -> 44650 | N28: =IFERROR(K28-I28,0) -> 0 | O28: =IFERROR(L28-#REF!,0) -> 0 | P28: =IFERROR(M28-#REF!,0) -> 0
A29: A.1.21 | B29: CA0000-89-REP-0001 | F29: 8405-PP-GE-017 | G29: PROJECT CLOSE OUT REPORT | H29: 2 | I29: 45524 | J29: 2 | K29: =IFERROR(VLOOKUP(C29,P6_Data!$B:$F,5,0),"") | L29: =IFERROR(VLOOKUP(D29,P6_Data!$B:$F,5,0),"") | M29: =IFERROR(VLOOKUP(E29,P6_Data!$B:$F,5,0),"") | N29: =IFERROR(K29-I29,0) -> 0 | O29: =IFERROR(L29-#REF!,0) -> 0 | P29: =IFERROR(M29-#REF!,0) -> 0
A30: A.1.22 | B30: CA0000-59-COD-0001 | F30: 8405-PP-GE-038 | G30: PROJECT COMPLETION DOSSIER | H30: 1 | I30: 45524 | J30: 1 | K30: =IFERROR(VLOOKUP(C30,P6_Data!$B:$F,5,0),"") | L30: =IFERROR(VLOOKUP(D30,P6_Data!$B:$F,5,0),"") | M30: =IFERROR(VLOOKUP(E30,P6_Data!$B:$F,5,0),"") | N30: =IFERROR(K30-I30,0) -> 0 | O30: =IFERROR(L30-#REF!,0) -> 0 | P30: =IFERROR(M30-#REF!,0) -> 0
A31: A.1.23 | B31: CA0000-59-PRO-0009 | F31: 8405-PP-GE-039 | G31: AS-BUILT DOCUMENTATION PROCEDURE | H31: 1 | I31: 45347 | J31: 1 | K31: =IFERROR(VLOOKUP(C31,P6_Data!$B:$F,5,0),"") | L31: =IFERROR(VLOOKUP(D31,P6_Data!$B:$F,5,0),"") | M31: =IFERROR(VLOOKUP(E31,P6_Data!$B:$F,5,0),"") | N31: =IFERROR(K31-I31,0) -> 0 | O31: =IFERROR(L31-#REF!,0) -> 0 | P31: =IFERROR(M31-#REF!,0) -> 0
A32: A.1.24 | B32: CA0000-59-PLN-0005 | C32: GDVPJ1260 | D32: GDVPJ1270 | E32: GDVPJ1280 | F32: 8405-PP-GE-018 | G32: LOGISTICS MANAGEMENT PLAN | H32: 3 | I32: 44739 | J32: 3 | K32: =IFERROR(VLOOKUP(C32,P6_Data!$B:$F,5,0),"") -> 44734 | L32: =IFERROR(VLOOKUP(D32,P6_Data!$B:$F,5,0),"") -> 44767 | M32: =IFERROR(VLOOKUP(E32,P6_Data!$B:$F,5,0),"") -> 44788 | N32: =IFERROR(K32-I32,0) -> -5 | O32: =IFERROR(L32-#REF!,0) -> 0 | P32: =IFERROR(M32-#REF!,0) -> 0
A33: A.1.25 | B33: CA0000-50-PRO-0009 | F33: 8405-PP-GE-033 | G33: LESSON LEARNT PROCEDURE | H33: 1 | I33: 44593 | J33: 1 | K33: =IFERROR(VLOOKUP(C33,P6_Data!$B:$F,5,0),"") | L33: =IFERROR(VLOOKUP(D33,P6_Data!$B:$F,5,0),"") | M33: =IFERROR(VLOOKUP(E33,P6_Data!$B:$F,5,0),"") | N33: =IFERROR(K33-I33,0) -> 0 | O33: =IFERROR(L33-#REF!,0) -> 0 | P33: =IFERROR(M33-#REF!,0) -> 0
A34: A.1.27 | B34: CA0000-89-REP-0002 | C34: GDVPJ1225 | D34: GDVPJ1230 | E34: GDVPJ1235 | F34: 8405-PP-GE-020 | G34: LESSON LEARNT WORKSHOP REPORT | H34: 2 | I34: 44671 | J34: 2 | K34: =IFERROR(VLOOKUP(C34,P6_Data!$B:$F,5,0),"") -> 44666 | L34: =IFERROR(VLOOKUP(D34,P6_Data!$B:$F,5,0),"") -> 44699 | M34: =IFERROR(VLOOKUP(E34,P6_Data!$B:$F,5,0),"") -> 44727 | N34: =IFERROR(K34-I34,0) -> -5 | O34: =IFERROR(L34-#REF!,0) -> 0 | P34: =IFERROR(M34-#REF!,0) -> 0
A35: A.1.28 | B35: CA0000-54-MAN-001 | F35: 8405-PP-CM-033 | G35: OPERATING MANUALS (VARIOUS DOCUMENTS) | H35: 2 | I35: 45524 | J35: 2 | K35: =IFERROR(VLOOKUP(C35,P6_Data!$B:$F,5,0),"") | L35: =IFERROR(VLOOKUP(D35,P6_Data!$B:$F,5,0),"") | M35: =IFERROR(VLOOKUP(E35,P6_Data!$B:$F,5,0),"") | N35: =IFERROR(K35-I35,0) -> 0 | O35: =IFERROR(L35-#REF!,0) -> 0 | P35: =IFERROR(M35-#REF!,0) -> 0
A36: A.1.29 | B36: CA0000-54-MAN-002 | F36: 8405-PP-CM-034 | G36: INSTALLATION AND MAINTENANCE MANUALS (VARIOUS DOCUMENTS) | H36: 2 | I36: 45524 | J36: 2 | K36: =IFERROR(VLOOKUP(C36,P6_Data!$B:$F,5,0),"") | L36: =IFERROR(VLOOKUP(D36,P6_Data!$B:$F,5,0),"") | M36: =IFERROR(VLOOKUP(E36,P6_Data!$B:$F,5,0),"") | N36: =IFERROR(K36-I36,0) -> 0 | O36: =IFERROR(L36-#REF!,0) -> 0 | P36: =IFERROR(M36-#REF!,0) -> 0
A37: A.1.30 | B37: CA0000-59-MAN-001 | F37: 8405-PP-GE-040 | G37: CERTIFICATION MANUAL (THIS DOCUMENT ALREADY SEND THRU LETTER NO. 8405-NPCC-A-L-0059 DATED 22-02-22 | H37: 3 | I37: 44614 | J37: 3 | K37: =IFERROR(VLOOKUP(C37,P6_Data!$B:$F,5,0),"") | L37: =IFERROR(VLOOKUP(D37,P6_Data!$B:$F,5,0),"") | M37: =IFERROR(VLOOKUP(E37,P6_Data!$B:$F,5,0),"") | N37: =IFERROR(K37-I37,0) -> 0 | O37: =IFERROR(L37-#REF!,0) -> 0 | P37: =IFERROR(M37-#REF!,0) -> 0
A38: A.1.31 | B38: CA0000-59-MAN-002 | F38: 8405-PP-GE-041 | G38: INDEXES FOR FINAL DOCUMENTATION MANUALS | H38: 3 | I38: 45458 | J38: 3 | K38: =IFERROR(VLOOKUP(C38,P6_Data!$B:$F,5,0),"") | L38: =IFERROR(VLOOKUP(D38,P6_Data!$B:$F,5,0),"") | M38: =IFERROR(VLOOKUP(E38,P6_Data!$B:$F,5,0),"") | N38: =IFERROR(K38-I38,0) -> 0 | O38: =IFERROR(L38-#REF!,0) -> 0 | P38: =IFERROR(M38-#REF!,0) -> 0
A39: A.1.32 | B39: CA0000-52-PLN-0008 | F39: 8405-PP-HS-023 | G39: TRAINING PLAN | H39: 3 | I39: 45433 | J39: 3 | K39: =IFERROR(VLOOKUP(C39,P6_Data!$B:$F,5,0),"") | L39: =IFERROR(VLOOKUP(D39,P6_Data!$B:$F,5,0),"") | M39: =IFERROR(VLOOKUP(E39,P6_Data!$B:$F,5,0),"") | N39: =IFERROR(K39-I39,0) -> 0 | O39: =IFERROR(L39-#REF!,0) -> 0 | P39: =IFERROR(M39-#REF!,0) -> 0
A40: A.1.33 | B40: CA0000-58-GDD-0001 | F40: 8405-PP-PR-012 | G40: CONTRACT ORGANIZATION AND MANNING, ORGANIZATION CHARTS | H40: 1 | I40: 44578 | J40: 1
...
